Workbook

Sheet Presupuesto
A2: PRESUPUESTO PALERMO JUNCAL
A4: No. | B4: DESCRIPCIÓN | C4: UNIDAD | D4: CANTIDAD | E4: A. MATERIAL | F4: B. MANO DE OBRA | G4: C. SERVICIO, EQUIPO, HERRAMIENTAS Y HSE | H4: D. TRANSPORTE | I4: E. VIATICOS | J4: PRECIO UNITARIO | K4: PRECIO TOTAL
A5: 1 | B5: MANO DE OBRA | K5: =SUM(K6:K39) -> 101655558
A6: 1.2 | B6: ='1.2'!B6:G6 -> APERTURA DE EXCAVACION POSTE DE 14 MTS M.T. RURAL | C6: UND | D6: =APU_P!N4 -> 2 | E6: ='1.2'!$H$17 -> 0 | F6: ='1.2'!$H$34 -> 184872.77 | G6: ='1.2'!$H$51 -> 23233.722 | H6: ='1.2'!$H$58 -> 0 | I6: ='1.2'!$H$65 -> 0 | J6: ='1.2'!F4 -> 208106.49 | K6: =ROUNDUP(Tabla1[[#This Row],[CANTIDAD]]*Tabla1[[#This Row],[PRECIO UNITARIO]],0) -> 416213
A7: 1.3 | B7: ='1.3'!B6:G6 -> APERTURA DE EXCAVACION PARA VIGUETA EN RETENIDA RURAL | C7: UND | D7: =APU_P!N5 -> 12 | E7: ='1.3'!$H$17 -> 0 | F7: ='1.3'!$H$34 -> 83520.324 | G7: ='1.3'!$H$51 -> 8712.6456 | H7: ='1.3'!$H$58 -> 0 | I7: ='1.3'!$H$65 -> 0 | J7: ='1.3'!F4 -> 92232.969 | K7: =ROUNDUP(Tabla1[[#This Row],[CANTIDAD]]*Tabla1[[#This Row],[PRECIO UNITARIO]],0) -> 1106796
A8: 1.6 | B8: ='1.6'!$B$6:$G$6 -> HINCADA, PLOMADA Y ORIENTACIÓN DE POSTE DE 14, 16 Y 18 MTS CON GRUA | C8: UND | D8: =APU_P!N6 -> 5 | E8: ='1.6'!$H$17 -> 0 | F8: ='1.6'!$H$34 -> 109533.17 | G8: ='1.6'!$H$51 -> 308712.65 | H8: ='1.6'!$H$58 -> 0 | I8: ='1.6'!$H$65 -> 0 | J8: ='1.6'!F4 -> 418245.81 | K8: =ROUNDUP(Tabla1[[#This Row],[CANTIDAD]]*Tabla1[[#This Row],[PRECIO UNITARIO]],0) -> 2091230
A9: 1.7 | B9: ='1.7'!$B$6:$G$6 -> INSTALACION LINE A TIERRA MEDIA TENSION | C9: UND | D9: =APU_P!N7 -> 4 | E9: ='1.7'!$H$17 -> 0 | F9: ='1.7'!$H$34 -> 136919.2 | G9: ='1.7'!$H$51 -> 6970.1165 | H9: ='1.7'!$H$58 -> 0 | I9: ='1.7'!$H$65 -> 0 | J9: ='1.7'!F4 -> 143889.32 | K9: =ROUNDUP(Tabla1[[#This Row],[CANTIDAD]]*Tabla1[[#This Row],[PRECIO UNITARIO]],0) -> 575558
A10: 1.8 | B10: ='1.8'!$B$6:$G$6 -> INSTALACIÓN DE TEMPLETE CUERDA GUITARRA CON TODOS SUS ACCESORIOS M.T. RURAL | C10: UND | D10: =APU_P!N8 -> 5 | E10: ='1.8'!$H$17 -> 0 | F10: ='1.8'!$H$34 -> 95832.542 | G10: ='1.8'!$H$51 -> 4646.7443 | H10: ='1.8'!$H$58 -> 0 | I10: ='1.8'!$H$65 -> 0 | J10: ='1.8'!F4 -> 100479.29 | K10: =ROUNDUP(Tabla1[[#This Row],[CANTIDAD]]*Tabla1[[#This Row],[PRECIO UNITARIO]],0) -> 502397
A11: 1.9 | B11: ='1.9'!B6:G6 -> RIEGA, TENDIDO Y TENSIONADO DE UN CABLE DE GUARDA | C11: KM | D11: =APU_P!N9 -> 0.716 | E11: ='1.9'!$H$17 -> 0 | F11: ='1.9'!$H$34 -> 648058.43 | G11: ='1.9'!$H$51 -> 511041.06 | H11: ='1.9'!$H$58 -> 210000 | I11: ='1.9'!$H$65 -> 0 | J11: ='1.9'!F4 -> 1369099.5 | K11: =ROUNDUP(Tabla1[[#This Row],[CANTIDAD]]*Tabla1[[#This Row],[PRECIO UNITARIO]],0) -> 980276
A12: 1.11 | B12: ='1.11'!B6:G6 -> TENDIDO Y TENSIONADO DE CABLE ECOLOGICO PARA RED MT TRIFASICA 36 KV DISPOSICION HORIZONTAL | C12: KM | D12: =APU_P!N11 -> 2.149 | E12: ='1.11'!$H$17 -> 0 | F12: ='1.11'!$H$34 -> 2466647.4 | G12: ='1.11'!$H$51 -> 1430245.4 | H12: ='1.11'!$H$58 -> 420000 | I12: ='1.11'!$H$65 -> 0 | J12: ='1.11'!F4 -> 4316892.8 | K12: =ROUNDUP(Tabla1[[#This Row],[CANTIDAD]]*Tabla1[[#This Row],[PRECIO UNITARIO]],0) -> 9277003
A13: 1.12 | B13: ='1.12'!$B$6:$G$6 -> TRANSPORTE DE POSTE 14 MTS M.T. RURAL DE BODEGA A SITIO CERCANO | C13: UND | D13: =APU_P!N12 -> 5 | E13: ='1.12'!$H$17 -> 0 | F13: ='1.12'!$H$34 -> 77975.29 | G13: ='1.12'!$H$51 -> 294701.17 | H13: ='1.12'!$H$58 -> 0 | I13: ='1.12'!$H$65 -> 0 | J13: ='1.12'!F4 -> 372676.45 | K13: =ROUNDUP(Tabla1[[#This Row],[CANTIDAD]]*Tabla1[[#This Row],[PRECIO UNITARIO]],0) -> 1863383
A14: 1.15 | B14: ='1.15'!$B$6:$G$6 -> VESTIDA DE ESTRUCTURA TRIFASICA DE PASO UN POSTE 13,8kV | C14: UND | D14: =APU_P!N15 -> 3 | E14: ='1.15'!$H$17 -> 0 | F14: ='1.15'!$H$34 -> 67418.622 | G14: ='1.15'!$H$51 -> 8712.6456 | H14: ='1.15'!$H$58 -> 26250 | I14: ='1.15'!$H$65 -> 0 | J14: ='1.15'!F4 -> 102381.27 | K14: =ROUNDUP(Tabla1[[#This Row],[CANTIDAD]]*Tabla1[[#This Row],[PRECIO UNITARIO]],0) -> 307144
A15: 1.16 | B15: ='1.16'!$B$6:$G$6 -> VESTIDA DE ESTRUCTURA TRIFASICA DE RETENCION UN POSTE 13,8 Kv | C15: UND | D15: =APU_P!N16 -> 2 | E15: ='1.16'!$H$17 -> 0 | F15: ='1.16'!$H$34 -> 89880.129 | G15: ='1.16'!$H$51 -> 11616.861 | H15: ='1.16'!$H$58 -> 35000 | I15: ='1.16'!$H$65 -> 0 | J15: ='1.16'!F4 -> 136496.99 | K15: =ROUNDUP(Tabla1[[#This Row],[CANTIDAD]]*Tabla1[[#This Row],[PRECIO UNITARIO]],0) -> 272994
A16: 1.17 | B16: ='1.17'!$B$6:$G$6 -> VESTIDA DE ESTRUCTURA TRIFASICA DE UN POSTE TIPO PASO 34.5 KV | C16: UND | D16: =APU_P!N17 -> 3 | E16: ='1.17'!$H$17 -> 0 | F16: ='1.17'!$H$34 -> 184702.7 | G16: ='1.17'!$H$51 -> 17425.291 | H16: ='1.17'!$H$58 -> 52500 | I16: ='1.17'!$H$65 -> 0 | J16: ='1.17'!F4 -> 254628 | K16: =ROUNDUP(Tabla1[[#This Row],[CANTIDAD]]*Tabla1[[#This Row],[PRECIO UNITARIO]],0) -> 763884
A17: 1.18 | B17: ='1.18'!$B$6:$G$6 -> VESTIDA DE ESTRUCTURA TRIFASICA DE UN POSTE TIPO RETENCIÓN - 34.5 KV | C17: UND | D17: =APU_P!N18 -> 5 | E17: ='1.18'!$H$17 -> 0 | F17: ='1.18'!$H$34 -> 246270.27 | G17: ='1.18'!$H$51 -> 23233.722 | H17: ='1.18'!$H$58 -> 70000 | I17: ='1.18'!$H$65 -> 0 | J17: ='1.18'!F4 -> 339503.99 | K17: =ROUNDUP(Tabla1[[#This Row],[CANTIDAD]]*Tabla1[[#This Row],[PRECIO UNITARIO]],0) -> 1697520
A18: 1.19 | B18: ='1.19'!B6:G6 -> VESTIDA ESTRUCTURA CABLE DE GUARDA - RETENCION | C18: UND | D18: =APU_P!N19 -> 3 | E18: ='1.19'!$H$17 -> 0 | F18: ='1.19'!$H$34 -> 65455.762 | G18: ='1.19'!$H$51 -> 9957.3093 | H18: ='1.19'!$H$58 -> 30000 | I18: ='1.19'!$H$65 -> 0 | J18: ='1.19'!F4 -> 105413.07 | K18: =ROUNDUP(Tabla1[[#This Row],[CANTIDAD]]*Tabla1[[#This Row],[PRECIO UNITARIO]],0) -> 316240
A19: 1.20 | B19: ='1.20'!B6:G6 -> VESTIDA ESTRUCTURA CABLE DE GUARDA DE PASO | C19: UND | D19: =APU_P!N20 -> 3 | E19: ='1.20'!$H$17 -> 0 | F19: ='1.20'!$H$34 -> 57273.791 | G19: ='1.20'!$H$51 -> 8712.6456 | H19: ='1.20'!$H$58 -> 26250 | I19: ='1.20'!$H$65 -> 0 | J19: ='1.20'!F4 -> 92236.437 | K19: =ROUNDUP(Tabla1[[#This Row],[CANTIDAD]]*Tabla1[[#This Row],[PRECIO UNITARIO]],0) -> 276710
A20: 1.21 | B20: ='1.21'!A1 -> DESVESTIDA ESTRUCTURA DE RETENCION MT RURAL | C20: UND | D20: =APU_P!N21 -> 3 | E20: ='1.21'!$H$17 -> 0 | F20: ='1.21'!$H$34 -> 136919.2 | G20: ='1.21'!$H$51 -> 6970.1165 | H20: ='1.21'!$H$58 -> 0 | I20: ='1.21'!$H$65 -> 0 | J20: ='1.21'!F4 -> 143889.32 | K20: =ROUNDUP(Tabla1[[#This Row],[CANTIDAD]]*Tabla1[[#This Row],[PRECIO UNITARIO]],0) -> 431668
A21: 1.22 | B21: ='1.22'!A1 -> DESVESTIDA ESTRUCTURA DE SUSPENSION MT RURAL | C21: UND | D21: =APU_P!N22 -> 1 | E21: ='1.22'!$H$17 -> 0 | F21: ='1.22'!$H$34 -> 95832.542 | G21: ='1.22'!$H$51 -> 4646.7443 | H21: ='1.22'!$H$58 -> 0 | I21: ='1.22'!$H$65 -> 0 | J21: ='1.22'!F4 -> 100479.29 | K21: =ROUNDUP(Tabla1[[#This Row],[CANTIDAD]]*Tabla1[[#This Row],[PRECIO UNITARIO]],0) -> 100480
A22: 1.23 | B22: ='1.23'!B6:G6 -> DESHINCADA DE POSTES 10, 12 Y 14 mts MT | C22: UND | D22: =APU_P!N23 -> 4 | E22: ='1.23'!$H$17 -> 0 | F22: ='1.23'!$H$34 -> 188203.38 | G22: ='1.23'!$H$51 -> 339701.17 | H22: ='1.23'!$H$58 -> 0 | I22: ='1.23'!$H$65 -> 0 | J22: ='1.23'!F4 -> 527904.55 | K22: =ROUNDUP(Tabla1[[#This Row],[CANTIDAD]]*Tabla1[[#This Row],[PRECIO UNITARIO]],0) -> 2111619
A23: 1.24 | B23: ='1.24'!B6:G6 -> INSTALACIÓN DE TEMPLETE SENCILLO CON TODOS SUS ACCESORIOS M.T. RURAL | C23: UND | D23: =APU_P!N24 -> 7 | E23: ='1.24'!$H$17 -> 0 | F23: ='1.24'!$H$34 -> 82136.989 | G23: ='1.24'!$H$51 -> 3872.2869 | H23: ='1.24'!$H$58 -> 0 | I23: ='1.24'!$H$65 -> 0 | J23: ='1.24'!F4 -> 86009.275 | K23: =ROUNDUP(Tabla1[[#This Row],[CANTIDAD]]*Tabla1[[#This Row],[PRECIO UNITARIO]],0) -> 602065
A24: 1.26 | B24: ='1.26'!B6:G6 -> TRANSPORTE DE POSTE RURAL DE SITIO CERCANO A BODEGA EH | C24: UND | D24: =APU_P!N26 -> 4 | E24: ='1.26'!$H$17 -> 0 | F24: ='1.26'!$H$34 -> 46034.989 | G24: ='1.26'!$H$51 -> 162923.6 | H24: ='1.26'!$H$58 -> 0 | I24: ='1.26'!$H$65 -> 0 | J24: ='1.26'!F4 -> 208958.59 | K24: =ROUNDUP(Tabla1[[#This Row],[CANTIDAD]]*Tabla1[[#This Row],[PRECIO UNITARIO]],0) -> 835835
A25: 1.27 | B25: ='1.27'!B6 -> DESMONTE DE TRANSFORMADOR MONOFASICO | C25: UND | D25: =APU_P!N27 -> 1 | E25: ='1.27'!$H$17 -> 0 | F25: ='1.27'!$H$34 -> 290740.35 | G25: ='1.27'!$H$51 -> 116168.61 | H25: ='1.27'!$H$58 -> 0 | I25: ='1.27'!$H$65 -> 0 | J25: ='1.27'!F4 -> 406908.96 | K25: =ROUNDUP(Tabla1[[#This Row],[CANTIDAD]]*Tabla1[[#This Row],[PRECIO UNITARIO]],0) -> 406909
A26: 1.28 | B26: ='1.28'!B6 -> MONTAJE DE TRANSFORMADOR MONOFASICO CON TODAS SUS PROTECCIONES RURAL | C26: UND | D26: =APU_P!N28 -> 1 | E26: ='1.28'!$H$17 -> 0 | F26: ='1.28'!$H$34 -> 391577.84 | G26: ='1.28'!$H$51 -> 348505.83 | H26: ='1.28'!$H$58 -> 0 | I26: ='1.28'!$H$65 -> 0 | J26: ='1.28'!F4 -> 740083.67 | K26: =ROUNDUP(Tabla1[[#This Row],[CANTIDAD]]*Tabla1[[#This Row],[PRECIO UNITARIO]],0) -> 740084
A27: 1.29 | B27: ='1.29'!B6:G6 -> DESVESTIDA DE ESTRUCTURA BT EXISTENTE | C27: UND | D27: =APU_P!N29 -> 2 | E27: ='1.29'!$H$17 -> 0 | F27: ='1.29'!$H$34 -> 45332.476 | G27: ='1.29'!$H$51 -> 20190 | H27: ='1.29'!$H$58 -> 0 | I27: ='1.29'!$H$65 -> 0 | J27: ='1.29'!F4 -> 65522.476 | K27: =ROUNDUP(Tabla1[[#This Row],[CANTIDAD]]*Tabla1[[#This Row],[PRECIO UNITARIO]],0) -> 131045
A28: 1.30 | B28: ='1.30'!B6:G6 -> VESTIDA DE ESTRUCTURA BT | C28: UND | D28: =APU_P!N30 -> 2 | E28: ='1.30'!$H$17 -> 0 | F28: ='1.30'!$H$34 -> 77259.417 | G28: ='1.30'!$H$51 -> 38250 | H28: ='1.30'!$H$58 -> 0 | I28: ='1.30'!$H$65 -> 0 | J28: ='1.30'!F4 -> 115509.42 | K28: =ROUNDUP(Tabla1[[#This Row],[CANTIDAD]]*Tabla1[[#This Row],[PRECIO UNITARIO]],0) -> 231019
A29: 1.31 | B29: ='1.31'!A1 -> DESMONTE, RECOGIDA Y ENROLLADO CABLE MT URBANO TRIFASICO | C29: Km | D29: =APU_P!N31 -> 1.47 | E29: ='1.31'!$H$17 -> 0 | F29: ='1.31'!$H$34 -> 33299.249 | G29: ='1.31'!$H$51 -> 477584.5 | H29: ='1.31'!$H$58 -> 0 | I29: ='1.31'!$H$65 -> 0 | J29: ='1.31'!F4 -> 510883.75 | K29: =ROUNDUP(Tabla1[[#This Row],[CANTIDAD]]*Tabla1[[#This Row],[PRECIO UNITARIO]],0) -> 751000
A30: 1.32 | B30: ='1.32'!B6 -> TENDIDO Y TENSIONADO DE CABLE ECOLOGICO PARA RED MT TRIFASICA 15 KV DISPOSICION HORIZONTAL | C30: Km | D30: =APU_P!N32 -> 1.47 | E30: ='1.32'!$H$17 -> 0 | F30: ='1.32'!$H$34 -> 2216152.2 | G30: ='1.32'!$H$51 -> 260177.36 | H30: ='1.32'!$H$58 -> 0 | I30: ='1.32'!$H$65 -> 0 | J30: ='1.32'!F4 -> 2476329.5 | K30: =ROUNDUP(Tabla1[[#This Row],[CANTIDAD]]*Tabla1[[#This Row],[PRECIO UNITARIO]],0) -> 3640205
A31: 1.33 | B31: ='1.33'!A1 -> INSTALACIÓN DE DEFENSA METALICA - ABATIMIENTO N2 | C31: M | D31: =APU_P!N33 -> 307 | E31: ='1.33'!$H$17 -> 0 | F31: ='1.33'!$H$34 -> 28788.144 | G31: ='1.33'!$H$51 -> 8712.775 | H31: ='1.33'!$H$58 -> 0 | I31: ='1.33'!$H$65 -> 0 | J31: ='1.33'!F4 -> 37500.919 | K31: =ROUNDUP(Tabla1[[#This Row],[CANTIDAD]]*Tabla1[[#This Row],[PRECIO UNITARIO]],0) -> 11512783
A32: 2.1 | B32: ='2.1'!$B$6:$G$6 -> INSTALACIÓN DE PLACAS DE IDENTIFICACIÓN DE PELIGRO RED ENERGIZADA (INCLUYE PLACA EN ACRILICO Y CONECTORES A RED) | C32: UND | D32: =APU_P!N34 -> 5 | E32: ='2.1'!$H$17 -> 35000 | F32: ='2.1'!$H$34 -> 5882.2661 | G32: ='2.1'!$H$51 -> 3485.0583 | H32: ='2.1'!$H$58 -> 0 | I32: ='2.1'!$H$65 -> 0 | J32: ='2.1'!F4 -> 44367.324 | K32: =ROUNDUP(Tabla1[[#This Row],[CANTIDAD]]*Tabla1[[#This Row],[PRECIO UNITARIO]],0) -> 221837
A33: 2.2 | B33: ='2.2'!$B$6:$G$6 -> INSTALACIÓN DE PLACAS DE IDENTIFICACIÓN DE POSTE, (INCLUYE PLACA DE ALUMINIO, CINTA BAND IT Y HEBILLA) | C33: UND | D33: =APU_P!N35 -> 5 | E33: ='2.2'!$H$17 -> 19590 | F33: ='2.2'!$H$34 -> 14760.758 | G33: ='2.2'!$H$51 -> 3485.0583 | H33: ='2.2'!$H$58 -> 0 | I33: ='2.2'!$H$65 -> 0 | J33: ='2.2'!F4 -> 37835.817 | K33: =ROUNDUP(Tabla1[[#This Row],[CANTIDAD]]*Tabla1[[#This Row],[PRECIO UNITARIO]],0) -> 189180
A34: 2.3 | B34: ='2.3'!$B$6:$G$6 -> LEVANTAMIENTO DE PLANO AS-BUILT DE OBRA CONSTRUIDA, GEOREFERENCIADA, MEDIA TENSIÓN Y BAJA TENSIÓN, INCLUYE REGISTRO FOTOGRÁFICO, COPIA FÍSICA Y ARCHIVOS EN CD | C34: UND | D34: =APU_P!N36 -> 1 | E34: ='2.3'!$H$17 -> 0 | F34: ='2.3'!$H$34 -> 2324579.3 | G34: ='2.3'!$H$51 -> 69701.165 | H34: ='2.3'!$H$58 -> 0 | I34: ='2.3'!$H$65 -> 0 | J34: ='2.3'!F4 -> 2394280.4 | K34: =ROUNDUP(Tabla1[[#This Row],[CANTIDAD]]*Tabla1[[#This Row],[PRECIO UNITARIO]],0) -> 2394281
A35: 2.4 | B35: ='2.4'!$B$6:$G$6 -> PREPARACION DISEÑO, MEMORIA DE CALCULO Y DEMAS DOCUMENTOS PARA CERTIFICACION RETIE (ART 10.1 DE RETIE-2013) | C35: UND | D35: =APU_P!N37 -> 1 | E35: ='2.4'!$H$17 -> 0 | F35: ='2.4'!$H$34 -> 10039483 | G35: ='2.4'!$H$51 -> 69701.165 | H35: ='2.4'!$H$58 -> 210000 | I35: ='2.4'!$H$65 -> 0 | J35: ='2.4'!F4 -> 10319185 | K35: =ROUNDUP(Tabla1[[#This Row],[CANTIDAD]]*Tabla1[[#This Row],[PRECIO UNITARIO]],0) -> 10319185
A36: 2.5 | B36: ='2.5'!$B$6:$G$6 -> REUNIR, DILIGENCIAR Y HACER ENTREGA DE LA INFORMACIÓN GENERAL DEL PROYECTO INCLUYENDO FORMATOS SPARD, INFORMES Y DOCUMENTOS REQUERIDOS POR EH SEGÚN FORMATO FT-DEX-03-004. ENTREGA FÍSICA Y MAGNÉTICA DE LA INFORMACIÓN | C36: UND | D36: =APU_P!N38 -> 1 | E36: ='2.5'!$H$17 -> 0 | F36: ='2.5'!$H$34 -> 603249.11 | G36: ='2.5'!$H$51 -> 0 | H36: ='2.5'!$H$58 -> 0 | I36: ='2.5'!$H$65 -> 0 | J36: ='2.5'!F4 -> 603249.11 | K36: =ROUNDUP(Tabla1[[#This Row],[CANTIDAD]]*Tabla1[[#This Row],[PRECIO UNITARIO]],0) -> 603250
A37: 2.6 | B37: ='2.6'!$B$6:$G$6 -> INSPECCION RETIE | C37: UND | D37: =APU_P!N39 -> 1 | E37: ='2.6'!$H$17 -> 12000000 | F37: ='2.6'!$H$34 -> 3327831.3 | G37: ='2.6'!$H$51 -> 69701.165 | H37: ='2.6'!$H$58 -> 630000 | I37: ='2.6'!$H$65 -> 0 | J37: ='2.6'!F4 -> 16027532 | K37: =ROUNDUP(Tabla1[[#This Row],[CANTIDAD]]*Tabla1[[#This Row],[PRECIO UNITARIO]],0) -> 16027533
A38: 3.1 | B38: ='3.1'!$B$6:$G$6 -> REDISEÑO DE RED NIVEL DE TENSIÓN DE 34,5KV/13,8KV | C38: UND | D38: =APU_P!N40 -> 1 | E38: ='3.1'!$H$17 -> 0 | F38: ='3.1'!$H$34 -> 13186233 | G38: ='3.1'!$H$51 -> 6069701.2 | H38: ='3.1'!$H$58 -> 840000 | I38: ='3.1'!$H$65 -> 0 | J38: ='3.1'!F4 -> 20095934 | K38: =ROUNDUP(Tabla1[[#This Row],[CANTIDAD]]*Tabla1[[#This Row],[PRECIO UNITARIO]],0) -> 20095935
A39: 3.2 | B39: ='3.2'!$B$6:$G$6 -> ELABORACIÓN DE DOSSIER Y MANUALES DE OPERACIÓN Y MANTENIMIENTO | C39: UND | D39: =APU_P!N41 -> 1 | E39: ='3.2'!$H$17 -> 0 | F39: ='3.2'!$H$34 -> 8952595.8 | G39: ='3.2'!$H$51 -> 69701.165 | H39: ='3.2'!$H$58 -> 840000 | I39: ='3.2'!$H$65 -> 0 | J39: ='3.2'!F4 -> 9862297 | K39: =ROUNDUP(Tabla1[[#This Row],[CANTIDAD]]*Tabla1[[#This Row],[PRECIO UNITARIO]],0) -> 9862297
A40: 4 | B40: SUMINISTRO MATERIALES | K40: =SUM(K41:K59) -> 281164761
A41: 4.1 | B41: ='4.1'!B6:G6 -> SUMINISTRO DE MATERIALES PARA ESTRUCTURA P103 N2 | C41: UND | D41: =APU_P!N42 -> 2 | E41: ='4.1'!$H$22 -> 387643.28 | F41: ='4.1'!$H$39 -> 0 | G41: ='4.1'!$H$56 -> 0 | H41: ='4.1'!$H$63 -> 42000 | I41: ='4.1'!$H$70 -> 0 | J41: ='4.1'!$F$4 -> 429643.28 | K41: =ROUNDUP(D41*J41,0) -> 859287
A42: 4.2 | B42: ='4.2'!B6:G6 -> SUMINISTRO DE MATERIALES PARA ESTRUCTURA P103 N3 | C42: UND | D42: =APU_P!N43 -> 3 | E42: ='4.2'!$H$22 -> 425060.34 | F42: ='4.2'!$H$39 -> 0 | G42: ='4.2'!$H$56 -> 0 | H42: ='4.2'!$H$63 -> 42000 | I42: ='4.2'!$H$70 -> 0 | J42: ='4.2'!$F$4 -> 467060.34 | K42: =ROUNDUP(D42*J42,0) -> 1401182
...

Sheet Actividades
A1: APOYO | C1: DESCRIPCIÓN | D1: Unidad | E1: Cantidad | F1: A. MATERIAL | G1: B. MANO DE OBRA | H1: C. SERVICIO, EQUIPO, HERRAMIENTAS Y HSE | I1: D. TRANSPORTE | J1: E. VIATICOS | K1: PRECIO UNITARIO | L1: PRECIO TOTAL
A2: E100 | B2: ACTIVIDAD | C2: Se instalará una estructura terminal 555 N3 con el fin de acoplar la linea 34,5kV proyectada con la existente | D2: GLB | E2: 1 | F2: =SUM(F3:F4) -> 1227542.3 | G2: =SUM(G3:G4) -> 246270.27 | H2: =SUM(H3:H4) -> 23233.722 | I2: =SUM(I3:I4) -> 112000 | J2: =SUM(J3:J4) -> 0 | K2: =SUM(K3:K4) -> 1609046.3 | L2: =SUM(L3:L4) -> 1609046.3
B3: 1.18 | C3: =VLOOKUP(B3,APU_P!$A$3:$M$59,2,FALSE) -> VESTIDA DE ESTRUCTURA TRIFASICA DE UN POSTE TIPO RETENCIÓN - 34.5 KV | D3: =VLOOKUP(B3,Presupuesto!$A$6:$K$58,3,FALSE) -> UND | E3: =VLOOKUP(B3,APU_P!$A$3:$M$56,3,FALSE) -> 1 | F3: =VLOOKUP($B$3,Presupuesto!$A$6:$K$58,5,FALSE) -> 0 | G3: =VLOOKUP(B3,Presupuesto!$A$6:$K$58,6,FALSE) -> 246270.27 | H3: =VLOOKUP(B3,Presupuesto!$A$6:$K$58,7,FALSE) -> 23233.722 | I3: =VLOOKUP(B3,Presupuesto!$A$6:$K$58,8,FALSE) -> 70000 | J3: =VLOOKUP(B3,Presupuesto!$A$6:$K$58,9,FALSE) -> 0 | K3: =VLOOKUP(B3,Presupuesto!$A$6:$K$58,10,FALSE) -> 339503.99 | L3: =E3*K3 -> 339503.99
B4: 4.8 | C4: =VLOOKUP(B4,APU_P!$A$3:$M$59,2,FALSE) -> SUMINISTRO DE MATERIALES PARA LA ESTRUCTURA 555 N3 | D4: =VLOOKUP(B4,Presupuesto!$A$6:$K$58,3,FALSE) -> UND | E4: 1 | F4: =VLOOKUP(B4,Presupuesto!$A$6:$K$58,5,FALSE) -> 1227542.3 | G4: =VLOOKUP(B4,Presupuesto!$A$6:$K$58,6,FALSE) -> 0 | H4: =VLOOKUP(B4,Presupuesto!$A$6:$K$58,7,FALSE) -> 0 | I4: =VLOOKUP(B4,Presupuesto!$A$6:$K$58,8,FALSE) -> 42000 | J4: =VLOOKUP(B4,Presupuesto!$A$6:$K$58,9,FALSE) -> 0 | K4: =VLOOKUP(B4,Presupuesto!$A$6:$K$58,10,FALSE) -> 1269542.3 | L4: =E4*K4 -> 1269542.3
A5: E97 | B5: ACTIVIDAD | C5: Se reemplazará el poste de concreto de 14m 1050 kg, se debe desvestir las estructuras instaladas, y retirar el poste. Posteriormente se hincará y vestira con las estructuras 619, 560 y 562 de retención para N1, N2 y N3 respectivamente. Además se harán excavaciones de viguetas para instalación de templetes, junto con la instalación del sistema de puesta a tierra. Al poste se instalará placas de peligro de red energizada y de identificación. | D5: GLB | E5: 1 | F5: =SUM(F6:F29) -> 8180100.6 | G5: =SUM(G6:G29) -> 1501916.2 | H5: =SUM(H6:H29) -> 1247428.5 | I5: =SUM(I6:I29) -> 534000 | J5: =SUM(J6:J29) -> 0 | K5: =SUM(K6:K29) -> 11463445 | L5: =SUM(L6:L29) -> 12110325
B6: ='Listado actividades'!A16 -> 1.3 | C6: =VLOOKUP(B6,APU_P!$A$3:$M$59,2,FALSE) -> APERTURA DE EXCAVACION PARA VIGUETA EN RETENIDA RURAL | D6: =VLOOKUP(B6,Presupuesto!$A$6:$K$58,3,FALSE) -> UND | E6: =VLOOKUP(B6,'Listado actividades'!$A$16:$C$40,3,FALSE) -> 3 | F6: =VLOOKUP(B6,Presupuesto!$A$6:$K$58,5,FALSE) -> 0 | G6: =VLOOKUP(B6,Presupuesto!$A$6:$K$58,6,FALSE) -> 83520.324 | H6: =VLOOKUP(B6,Presupuesto!$A$6:$K$58,7,FALSE) -> 8712.6456 | I6: =VLOOKUP(B6,Presupuesto!$A$6:$K$58,8,FALSE) -> 0 | J6: =VLOOKUP(B6,Presupuesto!$A$6:$K$58,9,FALSE) -> 0 | K6: =VLOOKUP(B6,Presupuesto!$A$6:$K$58,10,FALSE) -> 92232.969 | L6: =K6*E6 -> 276698.91
B7: ='Listado actividades'!A17 -> 1.6 | C7: =VLOOKUP(B7,APU_P!$A$3:$M$59,2,FALSE) -> HINCADA, PLOMADA Y ORIENTACIÓN DE POSTE DE 14, 16 Y 18 MTS CON GRUA | D7: =VLOOKUP(B7,Presupuesto!$A$6:$K$58,3,FALSE) -> UND | E7: =VLOOKUP(B7,'Listado actividades'!$A$16:$C$40,3,FALSE) -> 1 | F7: =VLOOKUP(B7,Presupuesto!$A$6:$K$58,5,FALSE) -> 0 | G7: =VLOOKUP(B7,Presupuesto!$A$6:$K$58,6,FALSE) -> 109533.17 | H7: =VLOOKUP(B7,Presupuesto!$A$6:$K$58,7,FALSE) -> 308712.65 | I7: =VLOOKUP(B7,Presupuesto!$A$6:$K$58,8,FALSE) -> 0 | J7: =VLOOKUP(B7,Presupuesto!$A$6:$K$58,9,FALSE) -> 0 | K7: =VLOOKUP(B7,Presupuesto!$A$6:$K$58,10,FALSE) -> 418245.81 | L7: =K7*E7 -> 418245.81
B8: ='Listado actividades'!A18 -> 1.7 | C8: =VLOOKUP(B8,APU_P!$A$3:$M$59,2,FALSE) -> INSTALACION LINE A TIERRA MEDIA TENSION | D8: =VLOOKUP(B8,Presupuesto!$A$6:$K$58,3,FALSE) -> UND | E8: =VLOOKUP(B8,'Listado actividades'!$A$16:$C$40,3,FALSE) -> 1 | F8: =VLOOKUP(B8,Presupuesto!$A$6:$K$58,5,FALSE) -> 0 | G8: =VLOOKUP(B8,Presupuesto!$A$6:$K$58,6,FALSE) -> 136919.2 | H8: =VLOOKUP(B8,Presupuesto!$A$6:$K$58,7,FALSE) -> 6970.1165 | I8: =VLOOKUP(B8,Presupuesto!$A$6:$K$58,8,FALSE) -> 0 | J8: =VLOOKUP(B8,Presupuesto!$A$6:$K$58,9,FALSE) -> 0 | K8: =VLOOKUP(B8,Presupuesto!$A$6:$K$58,10,FALSE) -> 143889.32 | L8: =K8*E8 -> 143889.32
B9: ='Listado actividades'!A19 -> 1.8 | C9: =VLOOKUP(B9,APU_P!$A$3:$M$59,2,FALSE) -> INSTALACIÓN DE TEMPLETE CUERDA GUITARRA CON TODOS SUS ACCESORIOS M.T. RURAL | D9: =VLOOKUP(B9,Presupuesto!$A$6:$K$58,3,FALSE) -> UND | E9: =VLOOKUP(B9,'Listado actividades'!$A$16:$C$40,3,FALSE) -> 1 | F9: =VLOOKUP(B9,Presupuesto!$A$6:$K$58,5,FALSE) -> 0 | G9: =VLOOKUP(B9,Presupuesto!$A$6:$K$58,6,FALSE) -> 95832.542 | H9: =VLOOKUP(B9,Presupuesto!$A$6:$K$58,7,FALSE) -> 4646.7443 | I9: =VLOOKUP(B9,Presupuesto!$A$6:$K$58,8,FALSE) -> 0 | J9: =VLOOKUP(B9,Presupuesto!$A$6:$K$58,9,FALSE) -> 0 | K9: =VLOOKUP(B9,Presupuesto!$A$6:$K$58,10,FALSE) -> 100479.29 | L9: =K9*E9 -> 100479.29
B10: ='Listado actividades'!A20 -> 1.12 | C10: =VLOOKUP(B10,APU_P!$A$3:$M$59,2,FALSE) -> TRANSPORTE DE POSTE 14 MTS M.T. RURAL DE BODEGA A SITIO CERCANO | D10: =VLOOKUP(B10,Presupuesto!$A$6:$K$58,3,FALSE) -> UND | E10: =VLOOKUP(B10,'Listado actividades'!$A$16:$C$40,3,FALSE) -> 1 | F10: =VLOOKUP(B10,Presupuesto!$A$6:$K$58,5,FALSE) -> 0 | G10: =VLOOKUP(B10,Presupuesto!$A$6:$K$58,6,FALSE) -> 77975.29 | H10: =VLOOKUP(B10,Presupuesto!$A$6:$K$58,7,FALSE) -> 294701.17 | I10: =VLOOKUP(B10,Presupuesto!$A$6:$K$58,8,FALSE) -> 0 | J10: =VLOOKUP(B10,Presupuesto!$A$6:$K$58,9,FALSE) -> 0 | K10: =VLOOKUP(B10,Presupuesto!$A$6:$K$58,10,FALSE) -> 372676.45 | L10: =K10*E10 -> 372676.45
B11: ='Listado actividades'!A21 -> 1.16 | C11: =VLOOKUP(B11,APU_P!$A$3:$M$59,2,FALSE) -> VESTIDA DE ESTRUCTURA TRIFASICA DE RETENCION UN POSTE 13,8 Kv | D11: =VLOOKUP(B11,Presupuesto!$A$6:$K$58,3,FALSE) -> UND | E11: =VLOOKUP(B11,'Listado actividades'!$A$16:$C$40,3,FALSE) -> 1 | F11: =VLOOKUP(B11,Presupuesto!$A$6:$K$58,5,FALSE) -> 0 | G11: =VLOOKUP(B11,Presupuesto!$A$6:$K$58,6,FALSE) -> 89880.129 | H11: =VLOOKUP(B11,Presupuesto!$A$6:$K$58,7,FALSE) -> 11616.861 | I11: =VLOOKUP(B11,Presupuesto!$A$6:$K$58,8,FALSE) -> 35000 | J11: =VLOOKUP(B11,Presupuesto!$A$6:$K$58,9,FALSE) -> 0 | K11: =VLOOKUP(B11,Presupuesto!$A$6:$K$58,10,FALSE) -> 136496.99 | L11: =K11*E11 -> 136496.99
B12: ='Listado actividades'!A22 -> 1.18 | C12: =VLOOKUP(B12,APU_P!$A$3:$M$59,2,FALSE) -> VESTIDA DE ESTRUCTURA TRIFASICA DE UN POSTE TIPO RETENCIÓN - 34.5 KV | D12: =VLOOKUP(B12,Presupuesto!$A$6:$K$58,3,FALSE) -> UND | E12: =VLOOKUP(B12,'Listado actividades'!$A$16:$C$40,3,FALSE) -> 1 | F12: =VLOOKUP(B12,Presupuesto!$A$6:$K$58,5,FALSE) -> 0 | G12: =VLOOKUP(B12,Presupuesto!$A$6:$K$58,6,FALSE) -> 246270.27 | H12: =VLOOKUP(B12,Presupuesto!$A$6:$K$58,7,FALSE) -> 23233.722 | I12: =VLOOKUP(B12,Presupuesto!$A$6:$K$58,8,FALSE) -> 70000 | J12: =VLOOKUP(B12,Presupuesto!$A$6:$K$58,9,FALSE) -> 0 | K12: =VLOOKUP(B12,Presupuesto!$A$6:$K$58,10,FALSE) -> 339503.99 | L12: =K12*E12 -> 339503.99
B13: ='Listado actividades'!A23 -> 1.19 | C13: =VLOOKUP(B13,APU_P!$A$3:$M$59,2,FALSE) -> VESTIDA ESTRUCTURA CABLE DE GUARDA - RETENCION | D13: =VLOOKUP(B13,Presupuesto!$A$6:$K$58,3,FALSE) -> UND | E13: =VLOOKUP(B13,'Listado actividades'!$A$16:$C$40,3,FALSE) -> 1 | F13: =VLOOKUP(B13,Presupuesto!$A$6:$K$58,5,FALSE) -> 0 | G13: =VLOOKUP(B13,Presupuesto!$A$6:$K$58,6,FALSE) -> 65455.762 | H13: =VLOOKUP(B13,Presupuesto!$A$6:$K$58,7,FALSE) -> 9957.3093 | I13: =VLOOKUP(B13,Presupuesto!$A$6:$K$58,8,FALSE) -> 30000 | J13: =VLOOKUP(B13,Presupuesto!$A$6:$K$58,9,FALSE) -> 0 | K13: =VLOOKUP(B13,Presupuesto!$A$6:$K$58,10,FALSE) -> 105413.07 | L13: =K13*E13 -> 105413.07
B14: ='Listado actividades'!A24 -> 1.21 | C14: =VLOOKUP(B14,APU_P!$A$3:$M$59,2,FALSE) -> DESVESTIDA ESTRUCTURA DE RETENCION MT RURAL | D14: =VLOOKUP(B14,Presupuesto!$A$6:$K$58,3,FALSE) -> UND | E14: =VLOOKUP(B14,'Listado actividades'!$A$16:$C$40,3,FALSE) -> 1 | F14: =VLOOKUP(B14,Presupuesto!$A$6:$K$58,5,FALSE) -> 0 | G14: =VLOOKUP(B14,Presupuesto!$A$6:$K$58,6,FALSE) -> 136919.2 | H14: =VLOOKUP(B14,Presupuesto!$A$6:$K$58,7,FALSE) -> 6970.1165 | I14: =VLOOKUP(B14,Presupuesto!$A$6:$K$58,8,FALSE) -> 0 | J14: =VLOOKUP(B14,Presupuesto!$A$6:$K$58,9,FALSE) -> 0 | K14: =VLOOKUP(B14,Presupuesto!$A$6:$K$58,10,FALSE) -> 143889.32 | L14: =K14*E14 -> 143889.32
B15: ='Listado actividades'!A25 -> 1.23 | C15: =VLOOKUP(B15,APU_P!$A$3:$M$59,2,FALSE) -> DESHINCADA DE POSTES 10, 12 Y 14 mts MT | D15: =VLOOKUP(B15,Presupuesto!$A$6:$K$58,3,FALSE) -> UND | E15: =VLOOKUP(B15,'Listado actividades'!$A$16:$C$40,3,FALSE) -> 1 | F15: =VLOOKUP(B15,Presupuesto!$A$6:$K$58,5,FALSE) -> 0 | G15: =VLOOKUP(B15,Presupuesto!$A$6:$K$58,6,FALSE) -> 188203.38 | H15: =VLOOKUP(B15,Presupuesto!$A$6:$K$58,7,FALSE) -> 339701.17 | I15: =VLOOKUP(B15,Presupuesto!$A$6:$K$58,8,FALSE) -> 0 | J15: =VLOOKUP(B15,Presupuesto!$A$6:$K$58,9,FALSE) -> 0 | K15: =VLOOKUP(B15,Presupuesto!$A$6:$K$58,10,FALSE) -> 527904.55 | L15: =K15*E15 -> 527904.55
B16: ='Listado actividades'!A26 -> 1.24 | C16: =VLOOKUP(B16,APU_P!$A$3:$M$59,2,FALSE) -> INSTALACIÓN DE TEMPLETE SENCILLO CON TODOS SUS ACCESORIOS M.T. RURAL | D16: =VLOOKUP(B16,Presupuesto!$A$6:$K$58,3,FALSE) -> UND | E16: =VLOOKUP(B16,'Listado actividades'!$A$16:$C$40,3,FALSE) -> 2 | F16: =VLOOKUP(B16,Presupuesto!$A$6:$K$58,5,FALSE) -> 0 | G16: =VLOOKUP(B16,Presupuesto!$A$6:$K$58,6,FALSE) -> 82136.989 | H16: =VLOOKUP(B16,Presupuesto!$A$6:$K$58,7,FALSE) -> 3872.2869 | I16: =VLOOKUP(B16,Presupuesto!$A$6:$K$58,8,FALSE) -> 0 | J16: =VLOOKUP(B16,Presupuesto!$A$6:$K$58,9,FALSE) -> 0 | K16: =VLOOKUP(B16,Presupuesto!$A$6:$K$58,10,FALSE) -> 86009.275 | L16: =K16*E16 -> 172018.55
B17: ='Listado actividades'!A28 -> 1.26 | C17: =VLOOKUP(B17,APU_P!$A$3:$M$59,2,FALSE) -> TRANSPORTE DE POSTE RURAL DE SITIO CERCANO A BODEGA EH | D17: =VLOOKUP(B17,Presupuesto!$A$6:$K$58,3,FALSE) -> UND | E17: =VLOOKUP(B17,'Listado actividades'!$A$16:$C$40,3,FALSE) -> 1 | F17: =VLOOKUP(B17,Presupuesto!$A$6:$K$58,5,FALSE) -> 0 | G17: =VLOOKUP(B17,Presupuesto!$A$6:$K$58,6,FALSE) -> 46034.989 | H17: =VLOOKUP(B17,Presupuesto!$A$6:$K$58,7,FALSE) -> 162923.6 | I17: =VLOOKUP(B17,Presupuesto!$A$6:$K$58,8,FALSE) -> 0 | J17: =VLOOKUP(B17,Presupuesto!$A$6:$K$58,9,FALSE) -> 0 | K17: =VLOOKUP(B17,Presupuesto!$A$6:$K$58,10,FALSE) -> 208958.59 | L17: =K17*E17 -> 208958.59
B18: ='Listado actividades'!A29 -> 1.29 | C18: =VLOOKUP(B18,APU_P!$A$3:$M$59,2,FALSE) -> DESVESTIDA DE ESTRUCTURA BT EXISTENTE | D18: =VLOOKUP(B18,Presupuesto!$A$6:$K$58,3,FALSE) -> UND | E18: =VLOOKUP(B18,'Listado actividades'!$A$16:$C$40,3,FALSE) -> 1 | F18: =VLOOKUP(B18,Presupuesto!$A$6:$K$58,5,FALSE) -> 0 | G18: =VLOOKUP(B18,Presupuesto!$A$6:$K$58,6,FALSE) -> 45332.476 | H18: =VLOOKUP(B18,Presupuesto!$A$6:$K$58,7,FALSE) -> 20190 | I18: =VLOOKUP(B18,Presupuesto!$A$6:$K$58,8,FALSE) -> 0 | J18: =VLOOKUP(B18,Presupuesto!$A$6:$K$58,9,FALSE) -> 0 | K18: =VLOOKUP(B18,Presupuesto!$A$6:$K$58,10,FALSE) -> 65522.476 | L18: =K18*E18 -> 65522.476
B19: ='Listado actividades'!A30 -> 1.30 | C19: =VLOOKUP(B19,APU_P!$A$3:$M$59,2,FALSE) -> VESTIDA DE ESTRUCTURA BT | D19: =VLOOKUP(B19,Presupuesto!$A$6:$K$58,3,FALSE) -> UND | E19: =VLOOKUP(B19,'Listado actividades'!$A$16:$C$40,3,FALSE) -> 1 | F19: =VLOOKUP(B19,Presupuesto!$A$6:$K$58,5,FALSE) -> 0 | G19: =VLOOKUP(B19,Presupuesto!$A$6:$K$58,6,FALSE) -> 77259.417 | H19: =VLOOKUP(B19,Presupuesto!$A$6:$K$58,7,FALSE) -> 38250 | I19: =VLOOKUP(B19,Presupuesto!$A$6:$K$58,8,FALSE) -> 0 | J19: =VLOOKUP(B19,Presupuesto!$A$6:$K$58,9,FALSE) -> 0 | K19: =VLOOKUP(B19,Presupuesto!$A$6:$K$58,10,FALSE) -> 115509.42 | L19: =K19*E19 -> 115509.42
B20: ='Listado actividades'!A31 -> 2.1 | C20: =VLOOKUP(B20,APU_P!$A$3:$M$59,2,FALSE) -> INSTALACIÓN DE PLACAS DE IDENTIFICACIÓN DE PELIGRO RED ENERGIZADA (INCLUYE PLACA EN ACRILICO Y CONECTORES A RED) | D20: =VLOOKUP(B20,Presupuesto!$A$6:$K$58,3,FALSE) -> UND | E20: =VLOOKUP(B20,'Listado actividades'!$A$16:$C$40,3,FALSE) -> 1 | F20: =VLOOKUP(B20,Presupuesto!$A$6:$K$58,5,FALSE) -> 35000 | G20: =VLOOKUP(B20,Presupuesto!$A$6:$K$58,6,FALSE) -> 5882.2661 | H20: =VLOOKUP(B20,Presupuesto!$A$6:$K$58,7,FALSE) -> 3485.0583 | I20: =VLOOKUP(B20,Presupuesto!$A$6:$K$58,8,FALSE) -> 0 | J20: =VLOOKUP(B20,Presupuesto!$A$6:$K$58,9,FALSE) -> 0 | K20: =VLOOKUP(B20,Presupuesto!$A$6:$K$58,10,FALSE) -> 44367.324 | L20: =K20*E20 -> 44367.324
B21: ='Listado actividades'!A32 -> 2.2 | C21: =VLOOKUP(B21,APU_P!$A$3:$M$59,2,FALSE) -> INSTALACIÓN DE PLACAS DE IDENTIFICACIÓN DE POSTE, (INCLUYE PLACA DE ALUMINIO, CINTA BAND IT Y HEBILLA) | D21: =VLOOKUP(B21,Presupuesto!$A$6:$K$58,3,FALSE) -> UND | E21: =VLOOKUP(B21,'Listado actividades'!$A$16:$C$40,3,FALSE) -> 1 | F21: =VLOOKUP(B21,Presupuesto!$A$6:$K$58,5,FALSE) -> 19590 | G21: =VLOOKUP(B21,Presupuesto!$A$6:$K$58,6,FALSE) -> 14760.758 | H21: =VLOOKUP(B21,Presupuesto!$A$6:$K$58,7,FALSE) -> 3485.0583 | I21: =VLOOKUP(B21,Presupuesto!$A$6:$K$58,8,FALSE) -> 0 | J21: =VLOOKUP(B21,Presupuesto!$A$6:$K$58,9,FALSE) -> 0 | K21: =VLOOKUP(B21,Presupuesto!$A$6:$K$58,10,FALSE) -> 37835.817 | L21: =K21*E21 -> 37835.817
B22: ='Listado actividades'!A33 -> 4.3 | C22: =VLOOKUP(B22,APU_P!$A$3:$M$59,2,FALSE) -> SUMINISTRO DE MATERIALES PARA LA ESTRUCTURA 560 N2 | D22: =VLOOKUP(B22,Presupuesto!$A$6:$K$58,3,FALSE) -> UND | E22: =VLOOKUP(B22,'Listado actividades'!$A$16:$C$40,3,FALSE) -> 1 | F22: =VLOOKUP(B22,Presupuesto!$A$6:$K$58,5,FALSE) -> 1743713.9 | G22: =VLOOKUP(B22,Presupuesto!$A$6:$K$58,6,FALSE) -> 0 | H22: =VLOOKUP(B22,Presupuesto!$A$6:$K$58,7,FALSE) -> 0 | I22: =VLOOKUP(B22,Presupuesto!$A$6:$K$58,8,FALSE) -> 42000 | J22: =VLOOKUP(B22,Presupuesto!$A$6:$K$58,9,FALSE) -> 0 | K22: =VLOOKUP(B22,Presupuesto!$A$6:$K$58,10,FALSE) -> 1785713.9 | L22: =K22*E22 -> 1785713.9
B23: ='Listado actividades'!A34 -> 4.4 | C23: =VLOOKUP(B23,APU_P!$A$3:$M$59,2,FALSE) -> SUMINISTRO DE MATERIALES PARA LA ESTRUCTURA 562 N2 | D23: =VLOOKUP(B23,Presupuesto!$A$6:$K$58,3,FALSE) -> UND | E23: =VLOOKUP(B23,'Listado actividades'!$A$16:$C$40,3,FALSE) -> 1 | F23: =VLOOKUP(B23,Presupuesto!$A$6:$K$58,5,FALSE) -> 2300879.1 | G23: =VLOOKUP(B23,Presupuesto!$A$6:$K$58,6,FALSE) -> 0 | H23: =VLOOKUP(B23,Presupuesto!$A$6:$K$58,7,FALSE) -> 0 | I23: =VLOOKUP(B23,Presupuesto!$A$6:$K$58,8,FALSE) -> 42000 | J23: =VLOOKUP(B23,Presupuesto!$A$6:$K$58,9,FALSE) -> 0 | K23: =VLOOKUP(B23,Presupuesto!$A$6:$K$58,10,FALSE) -> 2342879.1 | L23: =K23*E23 -> 2342879.1
B24: ='Listado actividades'!A35 -> 4.6 | C24: =VLOOKUP(B24,APU_P!$A$3:$M$59,2,FALSE) -> SUMINISTRO DE MATERIALES PARA LA ESTRUCTURA DE HILO DE GUARDA INDEPENDIENTE PARA ESTRUCTURA TIPO PASO HG-P | D24: =VLOOKUP(B24,Presupuesto!$A$6:$K$58,3,FALSE) -> UND | E24: =VLOOKUP(B24,'Listado actividades'!$A$16:$C$40,3,FALSE) -> 1 | F24: =VLOOKUP(B24,Presupuesto!$A$6:$K$58,5,FALSE) -> 107297.16 | G24: =VLOOKUP(B24,Presupuesto!$A$6:$K$58,6,FALSE) -> 0 | H24: =VLOOKUP(B24,Presupuesto!$A$6:$K$58,7,FALSE) -> 0 | I24: =VLOOKUP(B24,Presupuesto!$A$6:$K$58,8,FALSE) -> 42000 | J24: =VLOOKUP(B24,Presupuesto!$A$6:$K$58,9,FALSE) -> 0 | K24: =VLOOKUP(B24,Presupuesto!$A$6:$K$58,10,FALSE) -> 149297.16 | L24: =K24*E24 -> 149297.16
B25: ='Listado actividades'!A36 -> 4.9 | C25: =VLOOKUP(B25,APU_P!$A$3:$M$59,2,FALSE) -> SUMINISTRO DE MATERIALES PARA LA ESTRUCTURA 619 N1 | D25: =VLOOKUP(B25,Presupuesto!$A$6:$K$58,3,FALSE) -> UND | E25: =VLOOKUP(B25,'Listado actividades'!$A$16:$C$40,3,FALSE) -> 1 | F25: =VLOOKUP(B25,Presupuesto!$A$6:$K$58,5,FALSE) -> 57742.293 | G25: =VLOOKUP(B25,Presupuesto!$A$6:$K$58,6,FALSE) -> 0 | H25: =VLOOKUP(B25,Presupuesto!$A$6:$K$58,7,FALSE) -> 0 | I25: =VLOOKUP(B25,Presupuesto!$A$6:$K$58,8,FALSE) -> 42000 | J25: =VLOOKUP(B25,Presupuesto!$A$6:$K$58,9,FALSE) -> 0 | K25: =VLOOKUP(B25,Presupuesto!$A$6:$K$58,10,FALSE) -> 99742.293 | L25: =K25*E25 -> 99742.293
B26: ='Listado actividades'!A37 -> 4.10 | C26: =VLOOKUP(B26,APU_P!$A$3:$M$59,2,FALSE) -> SUMINISTRO DE TEMPLETE CUAERDA DE GUITARRA 34.5 KV | D26: =VLOOKUP(B26,Presupuesto!$A$6:$K$58,3,FALSE) -> UND | E26: =VLOOKUP(B26,'Listado actividades'!$A$16:$C$40,3,FALSE) -> 1 | F26: =VLOOKUP(B26,Presupuesto!$A$6:$K$58,5,FALSE) -> 416854.66 | G26: =VLOOKUP(B26,Presupuesto!$A$6:$K$58,6,FALSE) -> 0 | H26: =VLOOKUP(B26,Presupuesto!$A$6:$K$58,7,FALSE) -> 0 | I26: =VLOOKUP(B26,Presupuesto!$A$6:$K$58,8,FALSE) -> 42000 | J26: =VLOOKUP(B26,Presupuesto!$A$6:$K$58,9,FALSE) -> 0 | K26: =VLOOKUP(B26,Presupuesto!$A$6:$K$58,10,FALSE) -> 458854.66 | L26: =K26*E26 -> 458854.66
B27: ='Listado actividades'!A38 -> 4.11 | C27: =VLOOKUP(B27,APU_P!$A$3:$M$59,2,FALSE) -> SUMINISTRO DE TEMPLETE DIRECTO A VARILLA DE ANCLAJE 34.5 KV | D27: =VLOOKUP(B27,Presupuesto!$A$6:$K$58,3,FALSE) -> UND | E27: =VLOOKUP(B27,'Listado actividades'!$A$16:$C$40,3,FALSE) -> 2 | F27: =VLOOKUP(B27,Presupuesto!$A$6:$K$58,5,FALSE) -> 334404.16 | G27: =VLOOKUP(B27,Presupuesto!$A$6:$K$58,6,FALSE) -> 0 | H27: =VLOOKUP(B27,Presupuesto!$A$6:$K$58,7,FALSE) -> 0 | I27: =VLOOKUP(B27,Presupuesto!$A$6:$K$58,8,FALSE) -> 42000 | J27: =VLOOKUP(B27,Presupuesto!$A$6:$K$58,9,FALSE) -> 0 | K27: =VLOOKUP(B27,Presupuesto!$A$6:$K$58,10,FALSE) -> 376404.16 | L27: =K27*E27 -> 752808.32
B28: ='Listado actividades'!A39 -> 4.12 | C28: =VLOOKUP(B28,APU_P!$A$3:$M$59,2,FALSE) -> SUMINISTRO DE SISTEMA DE PUESTA A TIERRA REDES TRIFASICAS CON CABLE DE GUARDA POSTE SENCILLO | D28: =VLOOKUP(B28,Presupuesto!$A$6:$K$58,3,FALSE) -> UND | E28: =VLOOKUP(B28,'Listado actividades'!$A$16:$C$40,3,FALSE) -> 1 | F28: =VLOOKUP(B28,Presupuesto!$A$6:$K$58,5,FALSE) -> 117930.21 | G28: =VLOOKUP(B28,Presupuesto!$A$6:$K$58,6,FALSE) -> 0 | H28: =VLOOKUP(B28,Presupuesto!$A$6:$K$58,7,FALSE) -> 0 | I28: =VLOOKUP(B28,Presupuesto!$A$6:$K$58,8,FALSE) -> 42000 | J28: =VLOOKUP(B28,Presupuesto!$A$6:$K$58,9,FALSE) -> 0 | K28: =VLOOKUP(B28,Presupuesto!$A$6:$K$58,10,FALSE) -> 159930.21 | L28: =K28*E28 -> 159930.21
B29: ='Listado actividades'!A40 -> 4.17 | C29: =VLOOKUP(B29,APU_P!$A$3:$M$59,2,FALSE) -> SUMINISTRO DE POSTE DE CONCRETO DE 14 M X 1050 KGF VIBRADO Y REFORZADO | D29: =VLOOKUP(B29,Presupuesto!$A$6:$K$58,3,FALSE) -> UND | E29: =VLOOKUP(B29,'Listado actividades'!$A$16:$C$40,3,FALSE) -> 1 | F29: =VLOOKUP(B29,Presupuesto!$A$6:$K$58,5,FALSE) -> 3046689 | G29: =VLOOKUP(B29,Presupuesto!$A$6:$K$58,6,FALSE) -> 0 | H29: =VLOOKUP(B29,Presupuesto!$A$6:$K$58,7,FALSE) -> 0 | I29: =VLOOKUP(B29,Presupuesto!$A$6:$K$58,8,FALSE) -> 105000 | J29: =VLOOKUP(B29,Presupuesto!$A$6:$K$58,9,FALSE) -> 0 | K29: =VLOOKUP(B29,Presupuesto!$A$6:$K$58,10,FALSE) -> 3151689 | L29: =K29*E29 -> 3151689
A30: E96 | B30: ACTIVIDAD | C30: Se instalará una estructura trifásica tipo paso 103N3 y una estructura de hilo guarda tipo paso. | D30: GLB | E30: 1 | F30: =SUM(F31:F34) -> 532357.5 | G30: =SUM(G31:G34) -> 241976.5 | H30: =SUM(H31:H34) -> 26137.937 | I30: =SUM(I31:I34) -> 162750 | J30: =SUM(J31:J34) -> 0 | K30: =SUM(K31:K34) -> 963221.93 | L30: =SUM(L31:L34) -> 963221.93
B31: ='Listado actividades'!A44 -> 1.17 | C31: =VLOOKUP(B31,APU_P!$A$3:$M$59,2,FALSE) -> VESTIDA DE ESTRUCTURA TRIFASICA DE UN POSTE TIPO PASO 34.5 KV | D31: =VLOOKUP(B31,Presupuesto!$A$6:$K$58,3,FALSE) -> UND | E31: =VLOOKUP(B31,'Listado actividades'!$A$44:$C$47,3,FALSE) -> 1 | F31: =VLOOKUP(B31,Presupuesto!$A$6:$K$58,5,FALSE) -> 0 | G31: =VLOOKUP(B31,Presupuesto!$A$6:$K$58,6,FALSE) -> 184702.7 | H31: =VLOOKUP(B31,Presupuesto!$A$6:$K$58,7,FALSE) -> 17425.291 | I31: =VLOOKUP(B31,Presupuesto!$A$6:$K$58,8,FALSE) -> 52500 | J31: =VLOOKUP(B31,Presupuesto!$A$6:$K$58,9,FALSE) -> 0 | K31: =VLOOKUP(B31,Presupuesto!$A$6:$K$58,10,FALSE) -> 254628 | L31: =K31*E31 -> 254628
B32: ='Listado actividades'!A45 -> 1.20 | C32: =VLOOKUP(B32,APU_P!$A$3:$M$59,2,FALSE) -> VESTIDA ESTRUCTURA CABLE DE GUARDA DE PASO | D32: =VLOOKUP(B32,Presupuesto!$A$6:$K$58,3,FALSE) -> UND | E32: =VLOOKUP(B32,'Listado actividades'!$A$44:$C$47,3,FALSE) -> 1 | F32: =VLOOKUP(B32,Presupuesto!$A$6:$K$58,5,FALSE) -> 0 | G32: =VLOOKUP(B32,Presupuesto!$A$6:$K$58,6,FALSE) -> 57273.791 | H32: =VLOOKUP(B32,Presupuesto!$A$6:$K$58,7,FALSE) -> 8712.6456 | I32: =VLOOKUP(B32,Presupuesto!$A$6:$K$58,8,FALSE) -> 26250 | J32: =VLOOKUP(B32,Presupuesto!$A$6:$K$58,9,FALSE) -> 0 | K32: =VLOOKUP(B32,Presupuesto!$A$6:$K$58,10,FALSE) -> 92236.437 | L32: =K32*E32 -> 92236.437
B33: ='Listado actividades'!A46 -> 4.2 | C33: =VLOOKUP(B33,APU_P!$A$3:$M$59,2,FALSE) -> SUMINISTRO DE MATERIALES PARA LA ESTRUCTURA P103 N3 | D33: =VLOOKUP(B33,Presupuesto!$A$6:$K$58,3,FALSE) -> UND | E33: =VLOOKUP(B33,'Listado actividades'!$A$44:$C$47,3,FALSE) -> 1 | F33: =VLOOKUP(B33,Presupuesto!$A$6:$K$58,5,FALSE) -> 425060.34 | G33: =VLOOKUP(B33,Presupuesto!$A$6:$K$58,6,FALSE) -> 0 | H33: =VLOOKUP(B33,Presupuesto!$A$6:$K$58,7,FALSE) -> 0 | I33: =VLOOKUP(B33,Presupuesto!$A$6:$K$58,8,FALSE) -> 42000 | J33: =VLOOKUP(B33,Presupuesto!$A$6:$K$58,9,FALSE) -> 0 | K33: =VLOOKUP(B33,Presupuesto!$A$6:$K$58,10,FALSE) -> 467060.34 | L33: =K33*E33 -> 467060.34
B34: ='Listado actividades'!A47 -> 4.6 | C34: =VLOOKUP(B34,APU_P!$A$3:$M$59,2,FALSE) -> SUMINISTRO DE MATERIALES PARA LA ESTRUCTURA DE HILO DE GUARDA INDEPENDIENTE PARA ESTRUCTURA TIPO PASO HG-P | D34: =VLOOKUP(B34,Presupuesto!$A$6:$K$58,3,FALSE) -> UND | E34: =VLOOKUP(B34,'Listado actividades'!$A$44:$C$47,3,FALSE) -> 1 | F34: =VLOOKUP(B34,Presupuesto!$A$6:$K$58,5,FALSE) -> 107297.16 | G34: =VLOOKUP(B34,Presupuesto!$A$6:$K$58,6,FALSE) -> 0 | H34: =VLOOKUP(B34,Presupuesto!$A$6:$K$58,7,FALSE) -> 0 | I34: =VLOOKUP(B34,Presupuesto!$A$6:$K$58,8,FALSE) -> 42000 | J34: =VLOOKUP(B34,Presupuesto!$A$6:$K$58,9,FALSE) -> 0 | K34: =VLOOKUP(B34,Presupuesto!$A$6:$K$58,10,FALSE) -> 149297.16 | L34: =K34*E34 -> 149297.16
A35: E95D | B35: ACTIVIDAD | C35: Se reemplazará el poste de concreto de 14m por uno de 16m 1350 kg, se debe desvestir las estructuras instaladas, desmontar un transformador monofásico y retirar el poste. Posteriormente se hincará y vestirá el nuevo poste con las estructuras trifásicas 580 N2 y dos 555 N3. Se realizará el montaje del transformador monofásico. Además se harán excavaciones de viguetas para instalación de templetes, junto con la instalación del sistema de puesta a tierra. Al poste se le instalarán placas de peligro de red energizada y de identificación. | D35: GLB | E35: 1 | F35: =SUM(F36:F58) -> 8780623.3 | G35: =SUM(G36:G58) -> 2102097.4 | H35: =SUM(H36:H58) -> 1708230.6 | I35: =SUM(I36:I58) -> 450000 | J35: =SUM(J36:J58) -> 0 | K35: =SUM(K36:K58) -> 13040951 | L35: =SUM(L36:L58) -> 14962061
B36: ='Listado actividades'!A51 -> 1.3 | C36: =VLOOKUP(B36,APU_P!$A$3:$M$59,2,FALSE) -> APERTURA DE EXCAVACION PARA VIGUETA EN RETENIDA RURAL | D36: =VLOOKUP(B36,Presupuesto!$A$6:$K$58,3,FALSE) -> UND | E36: =VLOOKUP(B36,'Listado actividades'!$A$51:$C$74,3,FALSE) -> 2 | F36: =VLOOKUP(B36,Presupuesto!$A$6:$K$58,5,FALSE) -> 0 | G36: =VLOOKUP(B36,Presupuesto!$A$6:$K$58,6,FALSE) -> 83520.324 | H36: =VLOOKUP(B36,Presupuesto!$A$6:$K$58,7,FALSE) -> 8712.6456 | I36: =VLOOKUP(B36,Presupuesto!$A$6:$K$58,8,FALSE) -> 0 | J36: =VLOOKUP(B36,Presupuesto!$A$6:$K$58,9,FALSE) -> 0 | K36: =VLOOKUP(B36,Presupuesto!$A$6:$K$58,10,FALSE) -> 92232.969 | L36: =K36*E36 -> 184465.94
B37: ='Listado actividades'!A52 -> 1.6 | C37: =VLOOKUP(B37,APU_P!$A$3:$M$59,2,FALSE) -> HINCADA, PLOMADA Y ORIENTACIÓN DE POSTE DE 14, 16 Y 18 MTS CON GRUA | D37: =VLOOKUP(B37,Presupuesto!$A$6:$K$58,3,FALSE) -> UND | E37: =VLOOKUP(B37,'Listado actividades'!$A$51:$C$74,3,FALSE) -> 1 | F37: =VLOOKUP(B37,Presupuesto!$A$6:$K$58,5,FALSE) -> 0 | G37: =VLOOKUP(B37,Presupuesto!$A$6:$K$58,6,FALSE) -> 109533.17 | H37: =VLOOKUP(B37,Presupuesto!$A$6:$K$58,7,FALSE) -> 308712.65 | I37: =VLOOKUP(B37,Presupuesto!$A$6:$K$58,8,FALSE) -> 0 | J37: =VLOOKUP(B37,Presupuesto!$A$6:$K$58,9,FALSE) -> 0 | K37: =VLOOKUP(B37,Presupuesto!$A$6:$K$58,10,FALSE) -> 418245.81 | L37: =K37*E37 -> 418245.81
B38: ='Listado actividades'!A53 -> 1.7 | C38: =VLOOKUP(B38,APU_P!$A$3:$M$59,2,FALSE) -> INSTALACION LINE A TIERRA MEDIA TENSION | D38: =VLOOKUP(B38,Presupuesto!$A$6:$K$58,3,FALSE) -> UND | E38: =VLOOKUP(B38,'Listado actividades'!$A$51:$C$74,3,FALSE) -> 1 | F38: =VLOOKUP(B38,Presupuesto!$A$6:$K$58,5,FALSE) -> 0 | G38: =VLOOKUP(B38,Presupuesto!$A$6:$K$58,6,FALSE) -> 136919.2 | H38: =VLOOKUP(B38,Presupuesto!$A$6:$K$58,7,FALSE) -> 6970.1165 | I38: =VLOOKUP(B38,Presupuesto!$A$6:$K$58,8,FALSE) -> 0 | J38: =VLOOKUP(B38,Presupuesto!$A$6:$K$58,9,FALSE) -> 0 | K38: =VLOOKUP(B38,Presupuesto!$A$6:$K$58,10,FALSE) -> 143889.32 | L38: =K38*E38 -> 143889.32
B39: ='Listado actividades'!A54 -> 1.8 | C39: =VLOOKUP(B39,APU_P!$A$3:$M$59,2,FALSE) -> INSTALACIÓN DE TEMPLETE CUERDA GUITARRA CON TODOS SUS ACCESORIOS M.T. RURAL | D39: =VLOOKUP(B39,Presupuesto!$A$6:$K$58,3,FALSE) -> UND | E39: =VLOOKUP(B39,'Listado actividades'!$A$51:$C$74,3,FALSE) -> 2 | F39: =VLOOKUP(B39,Presupuesto!$A$6:$K$58,5,FALSE) -> 0 | G39: =VLOOKUP(B39,Presupuesto!$A$6:$K$58,6,FALSE) -> 95832.542 | H39: =VLOOKUP(B39,Presupuesto!$A$6:$K$58,7,FALSE) -> 4646.7443 | I39: =VLOOKUP(B39,Presupuesto!$A$6:$K$58,8,FALSE) -> 0 | J39: =VLOOKUP(B39,Presupuesto!$A$6:$K$58,9,FALSE) -> 0 | K39: =VLOOKUP(B39,Presupuesto!$A$6:$K$58,10,FALSE) -> 100479.29 | L39: =K39*E39 -> 200958.57
B40: ='Listado actividades'!A55 -> 1.12 | C40: =VLOOKUP(B40,APU_P!$A$3:$M$59,2,FALSE) -> TRANSPORTE DE POSTE 14 MTS M.T. RURAL DE BODEGA A SITIO CERCANO | D40: =VLOOKUP(B40,Presupuesto!$A$6:$K$58,3,FALSE) -> UND | E40: =VLOOKUP(B40,'Listado actividades'!$A$51:$C$74,3,FALSE) -> 1 | F40: =VLOOKUP(B40,Presupuesto!$A$6:$K$58,5,FALSE) -> 0 | G40: =VLOOKUP(B40,Presupuesto!$A$6:$K$58,6,FALSE) -> 77975.29 | H40: =VLOOKUP(B40,Presupuesto!$A$6:$K$58,7,FALSE) -> 294701.17 | I40: =VLOOKUP(B40,Presupuesto!$A$6:$K$58,8,FALSE) -> 0 | J40: =VLOOKUP(B40,Presupuesto!$A$6:$K$58,9,FALSE) -> 0 | K40: =VLOOKUP(B40,Presupuesto!$A$6:$K$58,10,FALSE) -> 372676.45 | L40: =K40*E40 -> 372676.45
...

Sheet Cotización materiales
A1: STOCK (bodega neiva) | C1: Código | D1: Material | E1: Unidad | F1: Cantidad | G1: Precios Unitario (COP) | K1: Precio Unitario | L1: TOTAL
A2: Código | B2: Cantidad | G2: ERI | H2: Distrieléctricos | I2: Internacional de eléctricos | J2: Otros
A3: 1- 04- 05- 1756 | B3: 1 | C3: 3301 | D3: ACCESORIOS PARA TEMPLETE CUERDA GUITARRA | E3: UND | F3: =VLOOKUP(C3,$C$185:$E$229,3,FALSE) -> 5 | G3: 0 | H3: 81137 | I3: 83764 | K3: =AVERAGEIF(G3:J3,">0") -> 82450.5 | L3: =K3*F3 -> 412252.5
A4: 1- 04- 05- 0016 | B4: 459 | C4: 621 | D4: AISLADOR TIPO CARRETE. ALTURA 76,2 MM ANSI 53-3 | E4: UND | F4: =VLOOKUP(C4,$C$185:$E$229,3,FALSE) -> 3 | J4: 4200 | K4: =AVERAGEIF(G4:J4,">0") -> 4200 | L4: =K4*F4 -> 12600
A5: 1- 04- 19- 0237 | B5: 56 | C5: 601 | D5: AISLADOR TIPO DISCO DE HORQUILLA. DIAMETRO 152 MM 13,2 KV ANSI 52-1 | E5: UND | F5: =VLOOKUP(C5,$C$185:$E$228,3,FALSE) -> 36 | G5: 113243.7 | H5: 45438 | I5: 90223 | K5: =AVERAGEIF(G5:J5,">0") -> 82968.233 | L5: =K5*F5 -> 2986856.4
A6: 1- 04- 05- 1579 | B6: 60 | C6: 603 | D6: AISLADOR TIPO DISCO DE HORQUILLA. DIAMETRO 254 MM 34.5 KV ANSI 52-4 | E6: UND | F6: =VLOOKUP(C6,$C$185:$E$228,3,FALSE) -> 72 | J6: 82950 | K6: =AVERAGEIF(G6:J6,">0") -> 82950 | L6: =K6*F6 -> 5972400
A7: 1- 04- 05- 0019 | B7: 194 | C7: 611 | D7: AISLADOR TIPO ESPIGO ROSCA 25,4MM 15kV ANSI 55-5 | E7: UND | F7: =VLOOKUP(C7,$C$185:$E$228,3,FALSE) -> 10 | G7: 77352.94 | H7: 43788 | I7: 60286 | K7: =AVERAGEIF(G7:J7,">0") -> 60475.647 | L7: =K7*F7 -> 604756.47
A8: 1- 04- 05- 0018 | B8: 184 | C8: 613 | D8: AISLADOR TIPO ESPIGO ROSCA 35MM 15kV ANSI 56-3 | E8: UND | F8: =VLOOKUP(C8,$C$185:$E$228,3,FALSE) -> 10 | J8: 73900 | K8: =AVERAGEIF(G8:J8,">0") -> 73900 | L8: =K8*F8 -> 739000
A9: 1- 04- 05- 0015 | B9: 366 | C9: 634 | D9: AISLADOR TIPO TENSOR ANSI 54-4 DE 6 3/4" PARA 34.5 KV | E9: UND | F9: =VLOOKUP(C9,$C$185:$E$228,3,FALSE) -> 9 | G9: 0 | H9: 5313 | I9: 0 | K9: =AVERAGEIF(G9:J9,">0") -> 5313 | L9: =K9*F9 -> 47817
A10: 1- 04- 19- 0242 | B10: 125 | C10: 2412 | D10: ARANDELA CUADRADA PLANA DE 51*17 MM Ø= 16 MM (2"X2"X5/8") | E10: UND | F10: =VLOOKUP(C10,$C$185:$E$228,3,FALSE) -> 19 | G10: 802.52 | H10: 726 | I10: 779 | K10: =AVERAGEIF(G10:J10,">0") -> 769.17333 | L10: =K10*F10 -> 14614.293
A11: 1- 04- 05- 0023 | B11: 550 | C11: 2433 | D11: ARANDELA DE PRESIÓN DE Ø= 26 MM PARA PERNO Ø= 13 MM (1/2") | E11: UND | F11: =VLOOKUP(C11,$C$185:$E$228,3,FALSE) -> 35 | G11: 168 | H11: 121 | I11: 121 | K11: =AVERAGEIF(G11:J11,">0") -> 136.66667 | L11: =K11*F11 -> 4783.3333
A12: 1- 04- 05- 0030 | B12: 1137 | C12: 2434 | D12: ARANDELA DE PRESIÓN DE Ø= 26 MM PARA PERNO Ø= 16 MM (5/8") | E12: UND | F12: =VLOOKUP(C12,$C$185:$E$228,3,FALSE) -> 167 | G12: 310.92 | H12: 260 | I12: 164 | K12: =AVERAGEIF(G12:J12,">0") -> 244.97333 | L12: =K12*F12 -> 40910.547
C13: 5 | D13: ABATIMIENTO N2 (PARALES 1500) 12m | E13: UND | F13: 2 | J13: 3416445 | K13: =AVERAGEIF(G13:J13,">0") -> 3416445 | L13: =K13*F13 -> 6832890
C14: 6 | D14: BARRERA METÁLICA DOBLE ONDA | E14: ML | F14: 307 | J14: 329300 | K14: =AVERAGEIF(G14:J14,">0") -> 329300 | L14: =K14*F14 -> 101095100
A15: 1- 04- 05- 1589 | B15: 10 | C15: 1903 | D15: BAYONETA SENCILLA, ESTRUCTURA EN ALINEAMIETO, 2 PERFORACIONES 11/16" DE 1,5 M | E15: UND | F15: =VLOOKUP(C15,$C$185:$E$228,3,FALSE) -> 4 | G15: 96470.59 | H15: 68750 | I15: 96637 | K15: =AVERAGEIF(G15:J15,">0") -> 87285.863 | L15: =K15*F15 -> 349143.45
A16: 1- 04- 01- 0011 | B16: 7529 | C16: 2815 | D16: CABLE DE ACERO GALVANIZADO TIPO SUPERRRESISTENTE PARA TEMPLETE DE 9,5 MM CON CARGA DE ROTURA 6980 KGF | E16: M | F16: =VLOOKUP(C16,$C$185:$E$228,3,FALSE) -> 180 | G16: 5567 | H16: 5000 | I16: 0 | K16: =AVERAGEIF(G16:J16,">0") -> 5283.5 | L16: =K16*F16 -> 951030
A17: 1- 04- 01- 0020 | B17: 1450 | C17: 803 | D17: CABLE DE COBRE DESNUDO CALIBRE 4 AWG | E17: M | F17: 56 | G17: 14226.89 | H17: 13324 | I17: 16881 | K17: =AVERAGEIF(G17:J17,">0") -> 14810.63 | L17: =K17*F17 -> 829395.28
C18: 7 | D18: CABLE DE ACERO GALVANIZADO EXTRARRESISTENTE DE 1/4 SUPER GX-3000 KGF (CABLE DE GUARDA) | E18: MTS | F18: 716 | G18: 2432.77 | H18: 2572 | K18: =AVERAGEIF(G18:J18,">0") -> 2502.385 | L18: =K18*F18 -> 1791707.7
A19: 1- 04- 01- 0143 | B19: 3783 | C19: 8 | D19: CABLE ECOLÓGICO TRICAPA NO 4/0 XLPE-TK 35KV CONDUCTOR ACSR | E19: MTS | F19: 2149 | G19: 35077.863 | H19: 33947 | K19: =AVERAGEIF(G19:J19,">0") -> 34512.431 | L19: =K19*F19 -> 74167215
A20: 1- 04- 01- 0173 | B20: 8964 | C20: 9 | D20: CABLE ECOLÓGICO TRICAPA NO 2/0 XLPE-TK 35KV CONDUCTOR ACSR | E20: MTS | F20: 1470 | G20: 28388.436 | H20: 27473 | K20: =AVERAGEIF(G20:J20,">0") -> 27930.718 | L20: =K20*F20 -> 41058156
C21: 10 | D21: CAPTAFARO B/B GALVANIZADO | E21: UND | F21: 76 | J21: 6535 | K21: =AVERAGEIF(G21:J21,">0") -> 6535 | L21: =K21*F21 -> 496660
A22: 1- 04- 05- 0054 | B22: 54 | C22: 1222 | D22: COLLARÍN DE DOS SALIDAS EN PLATINA DE HIERRO GALVANIZADO. DIAMETRO DEL POSTE 15 - 20 CM | E22: UND | F22: =VLOOKUP(C22,$C$185:$E$229,3,FALSE) -> 1 | G22: 20966.39 | H22: 15193 | I22: 19759 | K22: =AVERAGEIF(G22:J22,">0") -> 18639.463 | L22: =K22*F22 -> 18639.463
C23: 1214 | D23: COLLARÍN DE UNA SALIDA EN PLATINA DE HIERRO GALVANIZADO. DIAMETRO DEL POSTE 20 - 25 CM | E23: UND | F23: =VLOOKUP(C23,$C$185:$E$228,3,FALSE) -> 7 | G23: 25630.25 | H23: 23400 | I23: 20069.7 | K23: =AVERAGEIF(G23:J23,">0") -> 23033.317 | L23: =K23*F23 -> 161233.22
C24: 1202 | D24: COLLARÍN SIN SALIDA EN PLATINA DE HIERRO GALVANIZADO. DIAMETRO DEL POSTE 15 - 20 CM | E24: UND | F24: =VLOOKUP(C24,$C$185:$E$228,3,FALSE) -> 9 | G24: 0 | H24: 17272 | I24: 0 | K24: =AVERAGEIF(G24:J24,">0") -> 17272 | L24: =K24*F24 -> 155448
A25: 1- 04- 05- 1142 | B25: 50 | C25: 1 | D25: CONECTOR DE COMPRESIÓN TIPO C EN COBRE | E25: UND | F25: =VLOOKUP(C25,$C$185:$E$228,3,FALSE) -> 8 | J25: 8400 | K25: =AVERAGEIF(G25:J25,">0") -> 8400 | L25: =K25*F25 -> 67200
A26: 1- 04- 05- 1891 | B26: 50 | C26: 2 | D26: CONECTOR DE COMPRESIÓN TIPO PALA 4 AWG DE 1 HUECO | E26: UND | F26: =VLOOKUP(C26,$C$185:$E$228,3,FALSE) -> 8 | G26: 1681.51 | H26: 1820 | I26: 1573.29 | K26: =AVERAGEIF(G26:J26,">0") -> 1691.6 | L26: =K26*F26 -> 13532.8
A27: 1- 04- 05- 1297 | B27: 38 | C27: 1021 | D27: CONECTOR DE RANURAS PARALELAS DE UN PERNO. DIMENSIONES 35*45*45 MM | E27: UND | F27: =VLOOKUP(C27,$C$185:$E$228,3,FALSE) -> 42 | G27: 3521.01 | H27: 2210 | I27: 6099 | K27: =AVERAGEIF(G27:J27,">0") -> 3943.3367 | L27: =K27*F27 -> 165620.14
A28: 1- 04- 05- 0087 | B28: 448 | C28: 41062 | D28: CONECTOR TIPO TORNILLO PARA PUESTA A TIERRA | E28: UND | F28: =VLOOKUP(C28,$C$185:$E$228,3,FALSE) -> 4 | G28: 6243.7 | H28: 0 | I28: 0 | K28: =AVERAGEIF(G28:J28,">0") -> 6243.7 | L28: =K28*F28 -> 24974.8
A29: 1- 04- 05- 0838 | B29: 275 | C29: 3 | D29: CONECTOS COMPRESIÓN TIPO H | E29: UND | F29: =VLOOKUP(C29,$C$185:$E$228,3,FALSE) -> 4 | G29: 20336.13 | H29: 23887 | I29: 17726 | K29: =AVERAGEIF(G29:J29,">0") -> 20649.71 | L29: =K29*F29 -> 82598.84
A30: 1- 04- 05- 1401 | B30: 8 | C30: 268 | D30: CRUCETA METÁLICA DE ÁNGULO GALVANIZADO DE 2 M DE LONGITUD. CALIBRE (64*64*5) MM | E30: UND | F30: =VLOOKUP(C30,$C$185:$E$228,3,FALSE) -> 27 | G30: 123075.63 | H30: 130584 | I30: 108307 | K30: =AVERAGEIF(G30:J30,">0") -> 120655.54 | L30: =K30*F30 -> 3257699.7
A31: 1- 04- 05- 0111 | B31: 177 | C31: 332 | D31: DIAGONAL RECTA EN ÁNGULO PARA CRUCETA METÁLICA DE (38*38*5)MM - LONGITUD 1100MM | E31: UND | F31: =VLOOKUP(C31,$C$185:$E$228,3,FALSE) -> 19 | G31: 0 | H31: 16635 | I31: 0 | K31: =AVERAGEIF(G31:J31,">0") -> 16635 | L31: =K31*F31 -> 316065
A32: 1- 04- 05- 0110 | B32: 283 | C32: 333 | D32: DIAGONAL RECTA EN ÁNGULO PARA CRUCETA METÁLICA DE (38*38*5)MM - LONGITUD 680MM | E32: UND | F32: =VLOOKUP(C32,$C$185:$E$228,3,FALSE) -> 16 | G32: 20697.48 | H32: 16635 | I32: 18317 | K32: =AVERAGEIF(G32:J32,">0") -> 18549.827 | L32: =K32*F32 -> 296797.23
C33: 1601 | D33: ESLABÓN EN U CON PASADOR. DIMENSIONES 51 MM 8000 KGF | E33: UND | F33: =VLOOKUP(C33,$C$185:$E$228,3,FALSE) -> 10 | J33: 12750 | K33: =AVERAGEIF(G33:J33,">0") -> 12750 | L33: =K33*F33 -> 127500
A34: 1- 04- 05- 0116 | B34: 199 | C34: 2102 | D34: ESPÁRRAGO DE HIERRO GALVANIZADO ROSCADO EN TODA SU LONGITUD, 4 TUERCAS. DIAMETRO 16 MM LONGITUD 305 MM | E34: UND | F34: =VLOOKUP(C34,$C$185:$E$228,3,FALSE) -> 12 | G34: 11445.38 | H34: 5337 | I34: 7760 | K34: =AVERAGEIF(G34:J34,">0") -> 8180.7933 | L34: =K34*F34 -> 98169.52
A35: 1- 04- 05- 0413 | B35: 23 | C35: 2103 | D35: ESPÁRRAGO DE HIERRO GALVANIZADO ROSCADO EN TODA SU LONGITUD, 4 TUERCAS. DIAMETRO 16 MM LONGITUD 356 MM | E35: UND | F35: =VLOOKUP(C35,$C$185:$E$228,3,FALSE) -> 18 | J35: 8500 | K35: =AVERAGEIF(G35:J35,">0") -> 8500 | L35: =K35*F35 -> 153000
C36: 2105 | D36: ESPÁRRAGO DE HIERRO GALVANIZADO ROSCADO EN TODA SU LONGITUD, 4 TUERCAS. DIAMETRO 16 MM LONGITUD 458 MM | E36: UND | F36: =VLOOKUP(C36,$C$185:$E$228,3,FALSE) -> 3 | J36: 9200 | K36: =AVERAGEIF(G36:J36,">0") -> 9200 | L36: =K36*F36 -> 27600
A37: 1- 04- 05- 0122 | B37: 73 | C37: 511 | D37: ESPIGO DE ACERO GALVANIZADO ALTURA 150 MM DIAMETRO 19 MM PARA CRUCETA METÁLICA | E37: UND | F37: =VLOOKUP(C37,$C$185:$E$228,3,FALSE) -> 10 | G37: 16504 | H37: 8500 | I37: 0 | J37: 0 | K37: =AVERAGEIF(G37:J37,">0") -> 12502 | L37: =K37*F37 -> 125020
A38: 1- 04- 05- 0123 | B38: 40 | C38: 512 | D38: ESPIGO DE ACERO GALVANIZADO ALTURA 330 MM DIÁMETRO 35 MM PARA CRUCETA METÁLICA | E38: UND | F38: =VLOOKUP(C38,$C$185:$E$228,3,FALSE) -> 10 | J38: 11550 | K38: =AVERAGEIF(G38:J38,">0") -> 11550 | L38: =K38*F38 -> 115500
A39: 1- 04- 05- 0656 | B39: 754 | C39: 771 | D39: GRAPA PRENSADORA. DIÁMETRO DEL CONDUCTOR 6,35MM - 9,18MM DIMENSIONES 150*15MM | E39: UND | F39: =VLOOKUP(C39,$C$185:$E$228,3,FALSE) -> 36 | G39: 31684.87 | H39: 30355 | I39: 45571 | K39: =AVERAGEIF(G39:J39,">0") -> 35870.29 | L39: =K39*F39 -> 1291330.4
C40: 711 | D40: GRAPA TERMINAL O DE RETENCIÓN EN ACERO GALVANIZADO. CONDUCTORES AWG-MCM 6 - 2/0. 6000 KGF. | E40: UND | F40: =VLOOKUP(C40,$C$185:$E$228,3,FALSE) -> 42 | G40: 31684.87 | H40: 30355 | I40: 45571 | K40: =AVERAGEIF(G40:J40,">0") -> 35870.29 | L40: =K40*F40 -> 1506552.2
...

Sheet BD materiales
A1: Código | B1: Material
A2: 243 | B2: CRUCETA METÁLICA DE ÁNGULO GALVANIZADO DE 4 M DE LONGITUD. CALIBRE (76*76*6) MM
A3: 268 | B3: CRUCETA METÁLICA DE ÁNGULO GALVANIZADO DE 2 M DE LONGITUD. CALIBRE (64*64*5) MM
A4: 271 | B4: CRUCETA METÁLICA DE ÁNGULO GALVANIZADO DE 1,5 M DE LONGITUD. CALIBRE (63*63*5) MM
A5: 332 | B5: DIAGONAL RECTA EN ÁNGULO PARA CRUCETA METÁLICA DE (38*38*5)MM - LONGITUD 1100MM
A6: 333 | B6: DIAGONAL RECTA EN ÁNGULO PARA CRUCETA METÁLICA DE (38*38*5)MM - LONGITUD 680MM
A7: 351 | B7: DIAGONAL DE ARRIOSTRAMIENTO EN X DE 3M DE LONGITUD. CALIBRE (64*64*5) MM.
A8: 511 | B8: ESPIGO DE ACERO GALVANIZADO ALTURA 150 MM DIAMETRO 19 MM PARA CRUCETA METÁLICA
A9: 512 | B9: ESPIGO DE ACERO GALVANIZADO ALTURA 330 MM DIÁMETRO 35 MM PARA CRUCETA METÁLICA
A10: 601 | B10: AISLADOR TIPO DISCO DE HORQUILLA. DIAMETRO 152 MM 13,2 KV ANSI 52-1
A11: 603 | B11: AISLADOR TIPO DISCO DE HORQUILLA. DIAMETRO 254 MM 34.5 KV ANSI 52-4
A12: 611 | B12: AISLADOR TIPO ESPIGO ROSCA 25,4MM 15kV ANSI 55-5
A13: 613 | B13: AISLADOR TIPO ESPIGO ROSCA 35MM 15kV ANSI 56-3
... A94: 1222 | B94: COLLARÍN DE DOS SALIDAS EN PLATINA DE HIERRO GALVANIZADO. DIAMETRO DEL POSTE 15 - 20 CM

Sheet P103N2
A1: P-103 Circuito sencillo, aislamiento en espigo (PIN) disposición semibandera SIN HILO GUARDA | C1: Cantidades | E1: Cantidad de estructuras
C2: Unitaria | D2: Total
A3: Código | B3: Montaje de la Estructura | E3: =Info_P!B19 -> 2
A4: 268 | B4: =VLOOKUP(A4,'BD materiales'!$A$2:$B$93,2,FALSE) -> CRUCETA METÁLICA DE ÁNGULO GALVANIZADO DE 2 M DE LONGITUD. CALIBRE (64*64*5) MM | C4: 1 | D4: =C4*$E$3 -> 2
A5: 332 | B5: =VLOOKUP(A5,'BD materiales'!$A$2:$B$93,2,FALSE) -> DIAGONAL RECTA EN ÁNGULO PARA CRUCETA METÁLICA DE (38*38*5)MM - LONGITUD 1100MM | C5: 1 | D5: =C5*$E$3 -> 2
A6: 511 | B6: =VLOOKUP(A6,'BD materiales'!$A$2:$B$93,2,FALSE) -> ESPIGO DE ACERO GALVANIZADO ALTURA 150 MM DIAMETRO 19 MM PARA CRUCETA METÁLICA | C6: 3 | D6: =C6*$E$3 -> 6
A7: 611 | B7: =VLOOKUP(A7,'BD materiales'!$A$2:$B$93,2,FALSE) -> AISLADOR TIPO ESPIGO ROSCA 25,4MM 15kV ANSI 55-5 | C7: 3 | D7: =C7*$E$3 -> 6
A8: 1214 | B8: =VLOOKUP(A8,'BD materiales'!$A$2:$B$93,2,FALSE) -> COLLARÍN DE UNA SALIDA EN PLATINA DE HIERRO GALVANIZADO. DIAMETRO DEL POSTE 20 - 25 CM | C8: 1 | D8: =C8*$E$3 -> 2
A9: 2014 | B9: =VLOOKUP(A9,'BD materiales'!$A$2:$B$93,2,FALSE) -> PERNO DE MÁQUINA DE HIERRO GALVANIZADO CON CABEZA Y TUERCA CUADRADA. DIAMETRO 13 MM. LARGO 51 MM. | C9: 1 | D9: =C9*$E$3 -> 2
A10: 2034 | B10: =VLOOKUP(A10,'BD materiales'!$A$2:$B$93,2,FALSE) -> PERNO DE MÁQUINA DE HIERRO GALVANIZADO CON CABEZA Y TUERCA CUADRADA. DIAMETRO 16 MM. LARGO 254 MM. | C10: 1 | D10: =C10*$E$3 -> 2
A11: 2412 | B11: =VLOOKUP(A11,'BD materiales'!$A$2:$B$93,2,FALSE) -> ARANDELA CUADRADA PLANA DE 51*17 MM Ø= 16 MM (2"X2"X5/8") | C11: 1 | D11: =C11*$E$3 -> 2
A12: 2433 | B12: =VLOOKUP(A12,'BD materiales'!$A$2:$B$93,2,FALSE) -> ARANDELA DE PRESIÓN DE Ø= 26 MM PARA PERNO Ø= 13 MM (1/2") | C12: 1 | D12: =C12*$E$3 -> 2
A13: 2434 | B13: =VLOOKUP(A13,'BD materiales'!$A$2:$B$93,2,FALSE) -> ARANDELA DE PRESIÓN DE Ø= 26 MM PARA PERNO Ø= 16 MM (5/8") | C13: 1 | D13: =C13*$E$3 -> 2
A15: NOTA | B15: EL LISTADO NO CUENTA CON LA ESTRUCTURA DE HILO GUARDA

Sheet P103N3
A1: P-103 Circuito sencillo, aislamiento en espigo (PIN) disposición semibandera | C1: Cantidades | E1: Cantidad de estructuras
C2: Unitaria | D2: Total
A3: Código | B3: Montaje de la Estructura | E3: =Info_P!B21 -> 3
A4: 268 | B4: =VLOOKUP(A4,'BD materiales'!$A$2:$B$93,2,FALSE) -> CRUCETA METÁLICA DE ÁNGULO GALVANIZADO DE 2 M DE LONGITUD. CALIBRE (64*64*5) MM | C4: =SUMIF($A$20:$C$34,A4,$C$20:$C$34) -> 1 | D4: =C4*$E$3 -> 3
A5: 332 | B5: =VLOOKUP(A5,'BD materiales'!$A$2:$B$93,2,FALSE) -> DIAGONAL RECTA EN ÁNGULO PARA CRUCETA METÁLICA DE (38*38*5)MM - LONGITUD 1100MM | C5: =SUMIF($A$20:$C$34,A5,$C$20:$C$34) -> 1 | D5: =C5*$E$3 -> 3
A6: 512 | B6: =VLOOKUP(A6,'BD materiales'!$A$2:$B$93,2,FALSE) -> ESPIGO DE ACERO GALVANIZADO ALTURA 330 MM DIÁMETRO 35 MM PARA CRUCETA METÁLICA | C6: =SUMIF($A$20:$C$34,A6,$C$20:$C$34) -> 3 | D6: =C6*$E$3 -> 9
A7: 613 | B7: =VLOOKUP(A7,'BD materiales'!$A$2:$B$93,2,FALSE) -> AISLADOR TIPO ESPIGO ROSCA 35MM 15kV ANSI 56-3 | C7: =SUMIF($A$20:$C$34,A7,$C$20:$C$34) -> 3 | D7: =C7*$E$3 -> 9
A8: 1214 | B8: =VLOOKUP(A8,'BD materiales'!$A$2:$B$93,2,FALSE) -> COLLARÍN DE UNA SALIDA EN PLATINA DE HIERRO GALVANIZADO. DIAMETRO DEL POSTE 20 - 25 CM | C8: =SUMIF($A$20:$C$34,A8,$C$20:$C$34) -> 1 | D8: =C8*$E$3 -> 3
A9: 2014 | B9: =VLOOKUP(A9,'BD materiales'!$A$2:$B$93,2,FALSE) -> PERNO DE MÁQUINA DE HIERRO GALVANIZADO CON CABEZA Y TUERCA CUADRADA. DIAMETRO 13 MM. LARGO 51 MM. | C9: =SUMIF($A$20:$C$34,A9,$C$20:$C$34) -> 1 | D9: =C9*$E$3 -> 3
A10: 2034 | B10: =VLOOKUP(A10,'BD materiales'!$A$2:$B$93,2,FALSE) -> PERNO DE MÁQUINA DE HIERRO GALVANIZADO CON CABEZA Y TUERCA CUADRADA. DIAMETRO 16 MM. LARGO 254 MM. | C10: =SUMIF($A$20:$C$34,A10,$C$20:$C$34) -> 1 | D10: =C10*$E$3 -> 3
A11: 2412 | B11: =VLOOKUP(A11,'BD materiales'!$A$2:$B$93,2,FALSE) -> ARANDELA CUADRADA PLANA DE 51*17 MM Ø= 16 MM (2"X2"X5/8") | C11: =SUMIF($A$20:$C$34,A11,$C$20:$C$34) -> 1 | D11: =C11*$E$3 -> 3
A12: 2433 | B12: =VLOOKUP(A12,'BD materiales'!$A$2:$B$93,2,FALSE) -> ARANDELA DE PRESIÓN DE Ø= 26 MM PARA PERNO Ø= 13 MM (1/2") | C12: =SUMIF($A$20:$C$34,A12,$C$20:$C$34) -> 1 | D12: =C12*$E$3 -> 3
A13: 2434 | B13: =VLOOKUP(A13,'BD materiales'!$A$2:$B$93,2,FALSE) -> ARANDELA DE PRESIÓN DE Ø= 26 MM PARA PERNO Ø= 16 MM (5/8") | C13: =SUMIF($A$20:$C$34,A13,$C$20:$C$34) -> 1 | D13: =C13*$E$3 -> 3
A20: 268 | B20: =VLOOKUP(A20,[1]L.mat!$A$2:$B$83,2,FALSE) -> CRUCETA METÁLICA DE ÁNGULO GALVANIZADO DE 2 M DE LONGITUD. CALIBRE (64*64*5) MM | C20: 1
A21: 332 | B21: =VLOOKUP(A21,[1]L.mat!$A$2:$B$83,2,FALSE) -> DIAGONAL RECTA EN ÁNGULO PARA CRUCETA METÁLICA DE (38*38*5)MM - LONGITUD 1100MM | C21: 1
A22: 512 | B22: =VLOOKUP(A22,[1]L.mat!$A$2:$B$83,2,FALSE) -> ESPIGO DE ACERO GALVANIZADO ALTURA 330 MM DIÁMETRO 35 MM PARA CRUCETA METÁLICA | C22: 3
A23: 613 | B23: =VLOOKUP(A23,[1]L.mat!$A$2:$B$83,2,FALSE) -> AISLADOR TIPO ESPIGO ROSCA 35MM 15kV ANSI 56-3 | C23: 3
A24: 1214 | B24: =VLOOKUP(A24,[1]L.mat!$A$2:$B$83,2,FALSE) -> COLLARÍN DE UNA SALIDA EN PLATINA DE HIERRO GALVANIZADO. DIAMETRO DEL POSTE 20 - 25 CM | C24: 1
A25: 2014 | B25: =VLOOKUP(A25,[1]L.mat!$A$2:$B$83,2,FALSE) -> PERNO DE MÁQUINA DE HIERRO GALVANIZADO CON CABEZA Y TUERCA CUADRADA. DIAMETRO 13 MM. LARGO 51 MM. | C25: 1
A26: 2034 | B26: =VLOOKUP(A26,[1]L.mat!$A$2:$B$83,2,FALSE) -> PERNO DE MÁQUINA DE HIERRO GALVANIZADO CON CABEZA Y TUERCA CUADRADA. DIAMETRO 16 MM. LARGO 254 MM. | C26: 1
A27: 2412 | B27: =VLOOKUP(A27,[1]L.mat!$A$2:$B$83,2,FALSE) -> ARANDELA CUADRADA PLANA DE 51*17 MM Ø= 16 MM (2"X2"X5/8") | C27: 1
A28: 2433 | B28: =VLOOKUP(A28,[1]L.mat!$A$2:$B$83,2,FALSE) -> ARANDELA DE PRESIÓN DE Ø= 26 MM PARA PERNO Ø= 13 MM (1/2") | C28: 1
A29: 2434 | B29: =VLOOKUP(A29,[1]L.mat!$A$2:$B$83,2,FALSE) -> ARANDELA DE PRESIÓN DE Ø= 26 MM PARA PERNO Ø= 16 MM (5/8") | C29: 1

Sheet 560N2
A1: EH-NC-560 Circuito trifásico estructura de retención, disposición horizontal | C1: Cantidades | E1: Cantidad de estructuras
C2: Unitaria | D2: Total | E2: =Info_P!B18 -> 2
A3: Código | B3: Montaje de la Estructura
A4: 268 | B4: =VLOOKUP(A4,'BD materiales'!$A$2:$B$93,2,FALSE) -> CRUCETA METÁLICA DE ÁNGULO GALVANIZADO DE 2 M DE LONGITUD. CALIBRE (64*64*5) MM | C4: 2 | D4: =C4*$E$2 -> 4
A5: 333 | B5: =VLOOKUP(A5,'BD materiales'!$A$2:$B$93,2,FALSE) -> DIAGONAL RECTA EN ÁNGULO PARA CRUCETA METÁLICA DE (38*38*5)MM - LONGITUD 680MM | C5: 4 | D5: =C5*$E$2 -> 8
A6: 511 | B6: =VLOOKUP(A6,'BD materiales'!$A$2:$B$93,2,FALSE) -> ESPIGO DE ACERO GALVANIZADO ALTURA 150 MM DIAMETRO 19 MM PARA CRUCETA METÁLICA | C6: 1 | D6: =C6*$E$2 -> 2
A7: 601 | B7: =VLOOKUP(A7,'BD materiales'!$A$2:$B$93,2,FALSE) -> AISLADOR TIPO DISCO DE HORQUILLA. DIAMETRO 152 MM 13,2 KV ANSI 52-1 | C7: 12 | D7: =C7*$E$2 -> 24
A8: 611 | B8: =VLOOKUP(A8,'BD materiales'!$A$2:$B$93,2,FALSE) -> AISLADOR TIPO ESPIGO ROSCA 25,4MM 15kV ANSI 55-5 | C8: 1 | D8: =C8*$E$2 -> 2
A9: 711 | B9: =VLOOKUP(A9,'BD materiales'!$A$2:$B$93,2,FALSE) -> GRAPA TERMINAL O DE RETENCIÓN EN ACERO GALVANIZADO. CONDUCTORES AWG-MCM 6 - 2/0. 6000 KGF. | C9: 6 | D9: =C9*$E$2 -> 12
A10: 1021 | B10: =VLOOKUP(A10,'BD materiales'!$A$2:$B$93,2,FALSE) -> CONECTOR DE RANURAS PARALELAS DE UN PERNO. DIMENSIONES 35*45*45 MM | C10: 6 | D10: =C10*$E$2 -> 12
A11: 2014 | B11: =VLOOKUP(A11,'BD materiales'!$A$2:$B$93,2,FALSE) -> PERNO DE MÁQUINA DE HIERRO GALVANIZADO CON CABEZA Y TUERCA CUADRADA. DIAMETRO 13 MM. LARGO 51 MM. | C11: 4 | D11: =C11*$E$2 -> 8
A12: 2102 | B12: =VLOOKUP(A12,'BD materiales'!$A$2:$B$93,2,FALSE) -> ESPÁRRAGO DE HIERRO GALVANIZADO ROSCADO EN TODA SU LONGITUD, 4 TUERCAS. DIAMETRO 16 MM LONGITUD 305 MM | C12: 3 | D12: =C12*$E$2 -> 6
A13: 2433 | B13: =VLOOKUP(A13,'BD materiales'!$A$2:$B$93,2,FALSE) -> ARANDELA DE PRESIÓN DE Ø= 26 MM PARA PERNO Ø= 13 MM (1/2") | C13: 4 | D13: =C13*$E$2 -> 8
A14: 2434 | B14: =VLOOKUP(A14,'BD materiales'!$A$2:$B$93,2,FALSE) -> ARANDELA DE PRESIÓN DE Ø= 26 MM PARA PERNO Ø= 16 MM (5/8") | C14: 14 | D14: =C14*$E$2 -> 28
