Workbook
Name Bahías_de_Linea: 'N Bahias'!$N$11
Name Bahías_Equipadas_13_8_kV: 'N Bahias'!$B$28
Name Bahías_Equipadas_34_5_kV: 'N Bahias'!$B$27
Name Metros_Caseta_a_Patio: 'N Bahias'!$B$26
Name Pase_de_Vía: 'N Bahias'!$B$29
Name Reconectador: 'N Bahias'!$N$5
Name Seccionador_Tripolar: 'N Bahias'!$N$6
Name Seccionador_Tripolar_CSPT: 'N Bahias'!$N$7
Name tubo2: '[1]N Bahias'!$B$30
Name Tubos_1_1_2: 'N Bahias'!$B$33
Name Tubos_2: 'N Bahias'!$B$32
Name Tubos_3: 'N Bahias'!$B$31
Name Tubos_4: 'N Bahias'!$B$30

Sheet Material
A1: Ref | B1: Descripción | C1: Tarifa | D1: Unidad | E1: Valor comercial + IVA | F1: Rentabilidad | G1: Fecha | H1: Link
A2: MA-01 | B2: GRAPA DE RETENCIÓN TIPO PISTOLA DE 6-4/0 DE 3 UES EN ALUMINIO | C2: =E2*F2 -> 104000 | D2: UN | E2: 80000 | F2: 1.3 | G2: 45693 | H2: https://interelectricas.com.co/grapa-retencion/2885-grapa-retencion-aluminio-tipo-pistola-1-0-266-awg-3-ues.html
A3: MA-02 | B3: AISLADOR TIPO DISCO DE HORQUILLA. DIAMETRO 254 MM 34.5 KV ANSI 52-4 | C3: =E3*F3 -> 107835 | D3: UN | E3: 82950 | F3: 1.3 | G3: 45693 | H3: https://interelectricas.com.co/aisladores/2970-aislador-suspension-10-ansi-52-4-ansi-52-4.html
A4: MA-03 | B4: AISLADOR TIPO PIN DE PORCELANA PARA 34.5 KV ANSI 56-3 | C4: =E4*F4 -> 99645 | D4: UN | E4: 76650 | F4: 1.3 | G4: 45693 | H4: https://interelectricas.com.co/aisladores/1825-aislador-tipo-pin-o-para-espigo-de-34-5-kv-ansi-56-3.html
A5: MA-04 | B5: COLLARIN DE DOS SALIDAS EN PLATINA DE HIERRO GALVANIZADO. DIAMETRO (6-8 IN) (17 - 22 CM) | C5: =E5*F5 -> 24505 | D5: UN | E5: 18850 | F5: 1.3 | G5: 45693 | H5: https://interelectricas.com.co/herrajes-electricos/13-abrazadera-o-collarin-de-2-dos-salidas-7-8-pl-1-4-idem-180-mm.html
A6: MA-05 | B6: COLLARIN DE DOS SALIDAS EN PLATINA DE HIERRO GALVANIZADO. DIAMETRO (7-10 IN) (20 - 25 CM) | C6: =E6*F6 -> 27755 | D6: UN | E6: 21350 | F6: 1.3 | G6: 45693 | H6: https://interelectricas.com.co/herrajes-electricos/2405-abrazadera-o-collarin-de-2-dos-salidas-10-11-pl-1-4-idem-240-mm.html
A7: MA-06 | B7: COLLARIN DE DOS SALIDAS EN PLATINA DE HIERRO GALVANIZADO. DIAMETRO (10-12 IN) (25 - 30 CM) | C7: =E7*F7 -> 33150 | D7: UN | E7: 25500 | F7: 1.3 | G7: 45693 | H7: https://interelectricas.com.co/collarines-dos-salidas/10375-abrazadera-o-collarin-de-2-dos-salidas-11-12-platina-1-4-pulgada-280-mm.html
A8: MA-07 | B8: COLLARIN DE UNA SALIDA EN PLATINA DE HIERRO GALVANIZADO. DIAMETRO (14-16 IN) (35 - 40 CM) | C8: =E8*F8 -> 39000 | D8: UN | E8: 30000 | F8: 1.3 | G8: 45693 | H8: Precio Aproximado
A9: MA-08 | B9: CRUCETA METÁLICA DE ANGULO GALVANIZADO DE 6 M DE LONGITUD. CALIBRE (76*76*6) MM | C9: =E9*F9 -> 763908.6 | D9: UN | E9: 587622 | F9: 1.3 | G9: 45693 | H9: https://edelco.co/producto/cruceta-metalica-de-6-00-mts-3-x-3-x-1-4/?srsltid=AfmBOoqz5z8FW7naYbdZ7ujXYt8ZocEtWebPM92yPcy0DlncWGxFd0kI
A10: MA-09 | B10: ESPARRAGO DE HIERRO GALVANIZADO ROSCADO EN TODA SU LONGITUD, 4 TUERCAS. DIAMETRO 16 MM LONGITUD 458 MM | C10: =E10*F10 -> 10920 | D10: UN | E10: 8400 | F10: 1.3 | G10: 45693 | H10: https://interelectricas.com.co/herrajes-electricos/50-esparrago-de-5-8-x-16-4-t.html
A11: MA-10 | B11: GRAPA DE OPERAR EN CALIENTE CONDUCTOR AWG-MCM 6 - 400 DIÁMETRO 4 - 13,5 MM | C11: =E11*F11 -> 37155.3 | D11: UN | E11: 28581 | F11: 1.3 | G11: 45693 | H11: https://edelco.co/producto/grapa-de-operar-en-caliente-aluminio/?srsltid=AfmBOor3_12iyoeksqg9zdDRVfZriRBzsXlzXIl4RnW5E_avlI5oIcbF
A12: MA-11 | B12: TUERCA DE OJO ALARGADO PARA PERNO 16 MM | C12: =E12*F12 -> 18200 | D12: UN | E12: 14000 | F12: 1.3 | G12: 45693 | H12: https://interelectricas.com.co/herrajes-electricos/1-tuerca-de-ojo-alargado-de-5-8.html
A13: MA-12 | B13: POSTE DE CONCRETO 14 m 1050 KG | C13: =E13*F13 -> 2782325 | D13: UN | E13: 2140250 | F13: 1.3 | G13: 45693 | H13: https://interelectricas.com.co/postes-de-concreto-y-metalicos/2402-poste-de-concreto-pretensado-de-14-metros-1050-kg.html
A14: MA-13 | B14: MALLA ELECTROSOLDADA 4 mm | C14: 8577 | D14: M2 | E14: 16379 | F14: 1.3 | G14: 45694 | H14: Base de datos Ing Santiago 20/02/2025
A15: MA-14 | B15: CONCRETO DE 3000 PSI | C15: =E15*F15 -> 620227.23 | D15: M3 | E15: 477097.87 | F15: 1.3 | G15: 45694 | H15: apus_caldas_2021_1
A16: MA-15 | B16: VARILLA DE REFUERZO | C16: =E16*F16 -> 46020 | D16: ML | E16: 35400 | F16: 1.3 | G16: 45694 | H16: https://www.homecenter.com.co/homecenter-co/product/73638/varilla-corrugada-g60-w-5-5-8-pulg-x-6m/73638/
A17: MA-16 | B17: FORMALETA EN MADERA CON TABLA DE 1/4" | C17: =E17*F17 -> 104000 | D17: M2 | E17: 80000 | F17: 1.3 | G17: 45694 | H17: Precio Aproximado
A18: MA-17 | B18: EXCAVACIÓN EN MATERIAL COMÚN BAJO AGUA DE 0 - 2 M MANUAL | C18: =E18*F18 -> 45663.8 | D18: M3 | E18: 35126 | F18: 1.3 | G18: 45694 | H18: file:///D:/04.%20DISE%C3%91O%203%20(L.G)/13.%20ID20200070%20-%20%20S.E.%20BARAYA/154/APUs%20Gobernaci%C3%B3n%20de%20Risaralda.pdf
A19: MA-18 | B19: CABLE ACSR 4/0 AWG PARA CONEXIÓN ENTRE EQUIPOS | C19: =E19*F19 -> 10400 | D19: ML | E19: 8000 | F19: 1.3 | G19: 45455 | H19: cotización ie cinco sas
A20: MA-19 | B20: CABLE AAAC 465.4Kcmil – CAIRO PARA BARRAJE | C20: =E20*F20 -> 63707.162 | D20: ML | E20: 49005.509 | F20: 1.3 | G20: 45694 | H20: https://www.comercialvoltex.com/cable-de-aluminio-desnudo-cairo-2358mm2-19h?srsltid=AfmBOorbpMtA8DvXmg-4_AwIQTWnE-S39PGXS-yc9vBb8xDCcfU0Ebna
A21: MA-20 | B21: TRANSFORMADOR DE POTENCIA DE 5/6.25 MVA, REFRIGERACIÓN ONAN/ONAF, 34.5/13.8 KV, CONEXIÓN DYN5, CON ACCESORIOS DE CONTROL Y PROTECCIÓN INCLUYENDO: TERMÓMETROS CON CONTACTOS, NIVEL DE ACEITE CON CONTACTOS, VÁLVULA QUALITROL, RELÉ DE BUCHHOLZ, TANQUE DE EXPANSIÓN, SECADORES DE AIRE, VENTILADORES, TABLERO DE CONEXIONES ACOPLADO, CAMBIADOR DE TAP`S DE OPERACIÓN SIN CARGA EN 34.5 KV. | C21: =E21*F21 -> 972000000 | D21: UN | E21: =180000*'Precio Monedas'!B2 -> 810000000 | F21: 1.2 | G21: 45694 | H21: Precio dado en cotización
A22: MA-21 | B22: RECONECTADOR TRIFÁSICO (R). UM:36KV, IN: 630A, ISC:12.5KA MIN, LIWV:170KV. INCLUYE CONTROL MICROPROCESADOR DE ÚLTIMA TECNOLOGÍA, CABLES DE 6M, PRENSACABLES Y TARJETA DE COMUNICACIÓN LAN DUAL ETHERNET RJ45 Y ÓPTICA MTRJ, 3 SENSORES DE TENSIÓN, 3 SENSORES DE CORRIENTE, UN GABINETE DE COMUNICACIÓN QUE INCLUYA RADIO Y ANTENA, BATERIA DE RESPALDO Y CARGADOR. | C22: =E22*F22 -> 156633750 | D22: UN | E22: =22500*'Precio Monedas'!B2*1.19 -> 120487500 | F22: 1.3 | G22: 45695 | H22: Cotización ABB del 25/06/2025
A23: MA-22 | B23: SECCIONADOR TRIPOLAR MOTORIZADO CON CUCHILLA DE PUESTA A TIERRA MOTORIZADA UM:38 KV, IN: 630A, ISC:12.5KA MIN, LIWV:95KV. INCLUYE: BRAZO DE MANDO MANUAL A LA ALTURA APROPIADA | C23: =E23*F23 -> 57857275 | D23: UN | E23: 48214395 | F23: 1.2 | G23: 45695 | H23: https://energiaputumayo.com/testimonial/solicitud-publica-de-oferta-no-002-2024/
A24: MA-23 | B24: SECCIONADOR TRIPOLAR MOTORIZADO SIN CUCHILLA DE PUESTA A TIERRA. UM:38 KV, IN: 630A, ISC:12.5KA MIN, LIWV:95KV. INCLUYE: BRAZO DE MANDO MANUAL A LA ALTURA APROPIADA | C24: =E24*F24 -> 38388149 | D24: UN | E24: 31990124 | F24: 1.2 | G24: 45695 | H24: https://energiaputumayo.com/testimonial/solicitud-publica-de-oferta-no-002-2024/
A25: MA-24 | B25: DPS VNOM: 38KV. ISC 12.5 KA | C25: =E25*F25 -> 394810 | D25: UN | E25: 303700 | F25: 1.3 | G25: 45692 | H25: https://interelectricas.com.co/pararrayos/2845-pararrayo-polimerico-36kv-10ka-sin-herraje.html
A26: MA-25 | B26: CERTIFICACIÓN RETIE PARA BAHIA EN SUBESTACIÓN 34.5 KV O 13.8 KV | C26: =E26*F26 -> 9282000 | D26: UN | E26: =6000000*1.19 -> 7140000 | F26: 1.3 | G26: 45692 | H26: Precio cotización cinco sas
A27: MA-26 | B27: TRANSFORMADOR DE CORRIENTE. USO EXTERIOR. TRIPLE NÚCLEO: ( N1:500-1000/5 CL: 0,5S, N2:500-1000/5 CL: 0,5S, N3:500-1000/5 CL: 5P20) UM:38KV, ISC:12.5KA MIN, RELACIÓN DE TRANSFORMACIÓN AJUSTADA SEGÚN DISEÑO. INCLUYE PROTOCOLOS DE PRUEBA DE PRECISIÓN DE FABRICANTE Y LABORATORIO ACREDITADO. | C27: =E27*F27 -> 25061400 | D27: UN | E27: =3900*'Precio Monedas'!B2*1.19 -> 20884500 | F27: 1.2 | G27: 45695 | H27: Cotización ABB 25/06/2025
A28: MA-27 | B28: TRANSFORMADOR DE CORRIENTE. USO EXTERIOR. TRIPLE NÚCLEO: ( N1:75-150/5 CL: 0,5S, N2:75-150/5 CL: 0,5S, N3:75-150/5 CL: 5P20) UM:38KV, ISC:12.5KA MIN, RELACIÓN DE TRANSFORMACIÓN AJUSTADA SEGÚN DISEÑO. INCLUYE PROTOCOLOS DE PRUEBA DE PRECISIÓN DE FABRICANTE Y LABORATORIO ACREDITADO. | C28: =E28*F28 -> 23776200 | D28: UN | E28: =3700*'Precio Monedas'!B2*1.19 -> 19813500 | F28: 1.2 | G28: 45695 | H28: Cotización ABB 25/06/2025
A29: MA-28 | B29: TRANSFORMADOR DE CORRIENTE. USO EXTERIOR. TRIPLE NÚCLEO: ( N1:150-300/5 CL: 0,5S, N2:150-300/5 CL: 0,5S, N3:150-300/5 CL: 5P20). UM:38KV, ISC:12.5KA MIN, RELACIÓN DE TRANSFORMACIÓN AJUSTADA SEGÚN DISEÑO. INCLUYE PROTOCOLOS DE PRUEBA DE PRECISIÓN DE FABRICANTE Y LABORATORIO ACREDITADO. | C29: =E29*F29 -> 23776200 | D29: UN | E29: =3700*'Precio Monedas'!B2*1.19 -> 19813500 | F29: 1.2 | G29: 45695 | H29: Cotización ABB 25/06/2025
A30: MA-29 | B30: TRANSFORMADOR DE TENSIÓN. USO EXTERIOR. NUCLEO SENCILLO. (N1: 34,5√3/115√3. CL 0.5, 1 VA). | C30: =E30*F30 -> 21205800 | D30: UN | E30: =3300*'Precio Monedas'!B2*1.19 -> 17671500 | F30: 1.2 | G30: 45695 | H30: Cotización ABB 25/06/2025
A31: MA-30 | B31: TRANSFORMADOR DE TENSIÓN. USO EXTERIOR. DOBLE NUCLEO. (N1: 34,5√3/115√3. CL 0,5, 10 VA; N2: 34,5√3/115√3.CL 3P) | C31: =E31*F31 -> 21205800 | D31: UN | E31: =3300*'Precio Monedas'!B2*1.19 -> 17671500 | F31: 1.2 | G31: 45695 | H31: Cotización ABB 25/06/2025
A32: MA-31 | B32: TABLERO AUTOSOPORTADO DE FABRICACIÓN ESPECIAL. DE USO INTERIOR. IP 65. LAMINA DE ACERO GALVANIZADA CALIBRE 18. PARA ALBERGAR HASTA 6 EQUIPOS DE MEDIDA SEMIDIRECTA | C32: =E32*F32 -> 9100000 | D32: UN | E32: 7000000 | F32: 1.3 | G32: 45695 | H32: https://energiaputumayo.com/testimonial/solicitud-publica-de-oferta-no-002-2024/
A33: MA-32 | B33: LÁMPARA LED | C33: =E33*F33 -> 307373.88 | D33: UN | E33: 236441.45 | F33: 1.3 | G33: 45323 | H33: https://www.proelectrico.com/wp-content/uploads/2024/10/Lista-de-Precios-2024.pdf
A34: MA-33 | B34: RESISTENCIA DE CALEFACCIÓN PARA CUADROS ELÉCTRICOS 30W. IP20 | C34: =E34*F34 -> 262031.84 | D34: UN | E34: 201562.95 | F34: 1.3 | G34: 45323 | H34: https://www.proelectrico.com/wp-content/uploads/2024/10/Lista-de-Precios-2024.pdf
A35: MA-34 | B35: BREAKER DE RIEL MONOPOLAR 1 X 20 AMP 6 KA | C35: =E35*F35 -> 23790 | D35: UN | E35: 18300 | F35: 1.3 | G35: 45698 | H35: https://interelectricas.com.co/breakers/1251-breaker-abb-riel-monopolar-1x-20-amp-6ka.html
A36: MA-35 | B36: BLOQUE DE BORNERAS CORTOCIRCUITABLES DE CORRIENTE Y TENSIÓN | C36: =E36*F36 -> 1075128.6 | D36: UN | E36: 827022 | F36: 1.3 | G36: 44602 | H36: https://indeq.mx/products/2007-8874_wago?srsltid=AfmBOoqMCX4DEwTRrdD6rjJ4kbnuJzcZ_7UTCwmRHF9Ur0cCQfLdsPG6
A37: MA-36 | B37: CANALETAS RANURADA 40X60 MM | C37: =E37*F37 -> 31908.5 | D37: ML | E37: 24545 | F37: 1.3 | G37: 45695 | H37: https://edelco.co/producto/canaleta-ranurada-40-x-60-mm-x-2-00-mts-gris/?srsltid=AfmBOoqvhTSUJXrQuW2aS11-DQhcCgHpNx5sw4G8xMtrYQQAcFT7RGlh
A38: MA-37 | B38: MEDIDOR DE ENERGÍA KWH-KVARH CL 0.5S, DE CONEXIÓN INDIRECTA, MULTIFUNCIONAL CON INSTRUMENTACIÓN Y CURVA DE CARGA, MÍNIMO 8 CANALES, PUERTO ETERNET Y DOS PUERTOS SERIALES, CALIBRADO EN KWH Y KVARH CUATRO CUADRANTES Y BORNERAS CORTOCIRCUITABLES (+Q01A, +Q03A). INCLUYE PRUEBAS DE CALIBRACIÓN POR LABORATORIO ACREDITADO. | C38: =E38*F38 -> 3445591.5 | D38: UN | E38: 2650455 | F38: 1.3 | G38: 45698 | H38: https://autosolar.co/accesorios/medidor-bidireccional-elster-a1800?srsltid=AfmBOooDyoZ8fuMQZLwNErLrcR0phKpWED1SeYthFv3BnYjQ0ZN-_SK3
A39: MA-38 | B39: RELÉ (FUNCIONES: 50, 51, 50N, 51N, 50BFE1/E2,25, 27,59, 74, 79, 67, 67N, 81). PUERTO DE COMUNICACIÓN PARA FIBRA ÓPTICA, PROTOCOLO DE COMUNICACIÓN 61850. PANTALLA TACTIL (IHM). PARA LA BAHÍA DE LÍNEA | C39: =E39*F39 -> 23390640 | D39: UN | E39: =3360*'Precio Monedas'!B2*1.19 -> 17992800 | F39: 1.3 | G39: 45692 | H39: https://selinc.com/es/products/351/
A40: MA-39 | B40: RELE (FUNCIONES: 50, 51, 50N, 51N,50BFE1,E2,27,59,26,49,63,71,96,33,63Q). PUERTO DE COMUNICACIÓN PARA FIBRA ÓPTICA, PROTOCOLO DE COMUNICACIÓN 61850. PANTALLA TACTIL (IHM). PARA LA BAHÍA DE TRANSFORMADOR | C40: =E40*F40 -> 49023954 | D40: UN | E40: =7629*'Precio Monedas'!B2*1.19 -> 40853295 | F40: 1.2 | G40: 45692 | H40: Cotización ABB 25/06/2025
...

Sheet APUs
A1: Codigo APU | B1: Nombre APU | D1: Unidad APU | E1: Rendimiento | F1: Fecha | G1: Valor APU
A2: =Presupuesto!B6 -> 001_OC | B2: =Presupuesto!C6 -> COMPLEMENTACIÓN Y/O AJUSTE A ESTUDIOS Y DISEÑOS (INCLUYE LEVANTAMIENTO TOPOGRÁFICO, ESTUDIO DE SUELO, DISEÑO HIDRÁULICO E HIDROSANITARIO, DISEÑO ELÉCTRICO, DISEÑO ESTRUCTURAL) | D2: UN | E2: 2 | G2: =G64 -> 26197600
A3: A. MATERIAL
A4: Referencia | B4: Descripción | D4: Unidad | E4: Cantidad | F4: Vr. Unitario ($) | G4: Vr. Total ($)
A5: =Material!A580 -> MA-579 | B5: =IFERROR(VLOOKUP(A5,Material!$A:$H,2,0),"-") -> COMPLEMENTACIÓN Y/O AJUSTE A ESTUDIOS Y DISEÑOS (INCLUYE LEVANTAMIENTO TOPOGRÁFICO, ESTUDIO DE SUELO, DISEÑO HIDRÁULICO E HIDROSANITARIO, DISEÑO ELÉCTRICO, DISEÑO ESTRUCTURAL) | D5: =IFERROR(VLOOKUP(A5,Material!$A:$H,4,0),"-") -> UN | E5: 1 | F5: =IFERROR(VLOOKUP(A5,Material!$A:$H,3,0),"-") -> 20800000 | G5: =IFERROR(ROUNDUP(F5*E5,0),"-") -> 20800000
A6: Subtotal A | G6: =SUM(G5:G5) -> 20800000
A8: B. MANO DE OBRA
A9: Referencia | B9: Descripción | C9: Cantidad | D9: Fac. Sal | E9: Jornal ($) | F9: Prestaciones ($) | G9: Vr. Total ($)
A10: MO-1 | B10: =VLOOKUP(A10,'Componentes APUs'!$H$1:$L$25,2,0) -> Ingeniero Residente de Obra | C10: 0 | D10: =VLOOKUP(A10,'Componentes APUs'!$H$1:$L$25,3,0) -> 4 | E10: =VLOOKUP(A10,'Componentes APUs'!$H$1:$L$25,4,0) -> 271142.86 | F10: =VLOOKUP(A10,'Componentes APUs'!$H$1:$L$25,5,0) -> 162685.71 | G10: =ROUNDUP((E10+F10)*C10/E2,0) -> 0
A11: MO-3 | B11: =VLOOKUP(A11,'Componentes APUs'!$H$1:$L$25,2,0) -> Tecnico Liniero | C11: 0 | D11: =VLOOKUP(A11,'Componentes APUs'!$H$1:$L$25,3,0) -> 2 | E11: =VLOOKUP(A11,'Componentes APUs'!$H$1:$L$25,4,0) -> 154619.05 | F11: =VLOOKUP(A11,'Componentes APUs'!$H$1:$L$25,5,0) -> 92771.429 | G11: =ROUNDUP((E11+F11)*C11/E2,0) -> 0
A12: MO-8 | B12: =VLOOKUP(A12,'Componentes APUs'!$H$1:$L$25,2,0) -> Maestro de obra civil | C12: 0 | D12: =VLOOKUP(A12,'Componentes APUs'!$H$1:$L$25,3,0) -> 2.5 | E12: =VLOOKUP(A12,'Componentes APUs'!$H$1:$L$25,4,0) -> 169464.29 | F12: =VLOOKUP(A12,'Componentes APUs'!$H$1:$L$25,5,0) -> 101678.57 | G12: =ROUNDUP((E12+F12)*C12/E2,0) -> 0
A13: MO-9 | B13: =VLOOKUP(A13,'Componentes APUs'!$H$1:$L$25,2,0) -> Oficial de Obra Civil | C13: 0 | D13: =VLOOKUP(A13,'Componentes APUs'!$H$1:$L$25,3,0) -> 1.5 | E13: =VLOOKUP(A13,'Componentes APUs'!$H$1:$L$25,4,0) -> 115964.29 | F13: =VLOOKUP(A13,'Componentes APUs'!$H$1:$L$25,5,0) -> 69578.571 | G13: =ROUNDUP((E13+F13)*C13/E2,0) -> 0
A14: MO-5 | B14: =VLOOKUP(A14,'Componentes APUs'!$H$1:$L$25,2,0) -> Profesional en SST | C14: 0 | D14: =VLOOKUP(A14,'Componentes APUs'!$H$1:$L$25,3,0) -> 2.5 | E14: =VLOOKUP(A14,'Componentes APUs'!$H$1:$L$25,4,0) -> 169464.29 | F14: =VLOOKUP(A14,'Componentes APUs'!$H$1:$L$25,5,0) -> 101678.57 | G14: =ROUNDUP((E14+F14)*C14/E2,0) -> 0
A15: MO-6 | B15: =VLOOKUP(A15,'Componentes APUs'!$H$1:$L$25,2,0) -> Ayudante No Calificado | C15: 0 | D15: =VLOOKUP(A15,'Componentes APUs'!$H$1:$L$25,3,0) -> 1 | E15: =VLOOKUP(A15,'Componentes APUs'!$H$1:$L$25,4,0) -> 77309.524 | F15: =VLOOKUP(A15,'Componentes APUs'!$H$1:$L$25,5,0) -> 46385.714 | G15: =ROUNDUP((E15+F15)*C15/E2,0) -> 0
A16: Subtotal B | G16: =SUM(G10:G15) -> 0
A18: C. EQUIPOS Y HERRAMIENTAS
A19: Referencia | B19: Descripción | D19: Unidad | E19: Cantidad | F19: Vr. Unitario ($) | G19: Vr. Total ($)
A20: EH-1 | B20: =VLOOKUP(A20,'Componentes APUs'!$S$1:$V$10,2,0) -> Juego Llaves | D20: U | E20: 0 | F20: =VLOOKUP(A20,'Componentes APUs'!$S$1:$V$10,4,0) -> 9167 | G20: =ROUNDUP(F20*((E20/21)/E2),0) -> 0
A21: EH-2 | B21: =VLOOKUP(A21,'Componentes APUs'!$S$1:$V$10,2,0) -> Manila de servicio | D21: U | E21: 0 | F21: =VLOOKUP(A21,'Componentes APUs'!$S$1:$V$10,4,0) -> 2333 | G21: =ROUNDUP(F21*((E21/21)/E2),0) -> 0
A22: EH-3 | B22: =VLOOKUP(A22,'Componentes APUs'!$S$1:$V$10,2,0) -> Tula portaherramientas | D22: U | E22: 0 | F22: =VLOOKUP(A22,'Componentes APUs'!$S$1:$V$10,4,0) -> 1250 | G22: =ROUNDUP(F22*((E22/21)/E2),0) -> 0
A23: EH-4 | B23: =VLOOKUP(A23,'Componentes APUs'!$S$1:$V$10,2,0) -> Agarradoras | D23: U | E23: 0 | F23: =VLOOKUP(A23,'Componentes APUs'!$S$1:$V$10,4,0) -> 125000 | G23: =ROUNDUP(F23*((E23/21)/E2),0) -> 0
A24: EH-5 | B24: =VLOOKUP(A24,'Componentes APUs'!$S$1:$V$10,2,0) -> Templadoras | D24: U | E24: 0 | F24: =VLOOKUP(A24,'Componentes APUs'!$S$1:$V$10,4,0) -> 250000 | G24: =ROUNDUP(F24*((E24/21)/E2),0) -> 0
A25: EH-6 | B25: =VLOOKUP(A25,'Componentes APUs'!$S$1:$V$10,2,0) -> Herramienta Menor | D25: U | E25: 0 | F25: =VLOOKUP(A25,'Componentes APUs'!$S$1:$V$10,4,0) -> 75758 | G25: =ROUNDUP(F25*((E25/21)/E2),0) -> 0
A26: Subtotal C | G26: =SUM(G20:G25) -> 0
A28: D. EPP Y DOTACION
A29: Referencia | B29: Descripción | D29: Unidad | E29: Cantidad | F29: Vr. Unitario ($) | G29: Vr. Total ($)
A30: ED-1 | B30: =VLOOKUP(A30,'Componentes APUs'!$A$1:$D$14,2,0) -> Camisa indigo sin partes metalicas | D30: =VLOOKUP(A30,'Componentes APUs'!$A$1:$D$14,3,0) -> U | E30: =SUM(C10:C15) -> 0 | F30: =VLOOKUP(A30,'Componentes APUs'!$A$1:$D$14,4,0) -> 8585.8586 | G30: =ROUNDUP(F30*(E30/21)/E2,0) -> 0
A31: ED-2 | B31: =VLOOKUP(A31,'Componentes APUs'!$A$1:$D$14,2,0) -> Bota de seguridad dielectrica | D31: =VLOOKUP(A31,'Componentes APUs'!$A$1:$D$14,3,0) -> Par | E31: =SUM(C10:C15) -> 0 | F31: =VLOOKUP(A31,'Componentes APUs'!$A$1:$D$14,4,0) -> 7500 | G31: =ROUNDUP(F31*(E31/21)/E2,0) -> 0
A32: ED-3 | B32: =VLOOKUP(A32,'Componentes APUs'!$A$1:$D$14,2,0) -> Casco dielectrico Tipo 1 Clase E con barbuquejo | D32: =VLOOKUP(A32,'Componentes APUs'!$A$1:$D$14,3,0) -> U | E32: =C10+C11+C13+C14+C15+IF(A12<>"MO-3",C12,0) -> 0 | F32: =VLOOKUP(A32,'Componentes APUs'!$A$1:$D$14,4,0) -> 10101.01 | G32: =ROUNDUP(F32*(E32/21)/E2,0) -> 0
A33: ED-4 | B33: =VLOOKUP(A33,'Componentes APUs'!$A$1:$D$14,2,0) -> Correa plastica y antiflama | D33: =VLOOKUP(A33,'Componentes APUs'!$A$1:$D$14,3,0) -> U | E33: =SUM(C10:C15) -> 0 | F33: =VLOOKUP(A33,'Componentes APUs'!$A$1:$D$14,4,0) -> 3787.8788 | G33: =ROUNDUP(F33*(E33/21)/E2,0) -> 0
A34: ED-5 | B34: =VLOOKUP(A34,'Componentes APUs'!$A$1:$D$14,2,0) -> Gafas protectoras filtro UV | D34: =VLOOKUP(A34,'Componentes APUs'!$A$1:$D$14,3,0) -> U | E34: =SUM(C10:C15) -> 0 | F34: =VLOOKUP(A34,'Componentes APUs'!$A$1:$D$14,4,0) -> 2777.7778 | G34: =ROUNDUP(F34*(E34/21)/E2,0) -> 0
A35: ED-6 | B35: =VLOOKUP(A35,'Componentes APUs'!$A$1:$D$14,2,0) -> Bota de seguridad PVC dielectrica | D35: =VLOOKUP(A35,'Componentes APUs'!$A$1:$D$14,3,0) -> Par | E35: =SUM(C10:C15) -> 0 | F35: =VLOOKUP(A35,'Componentes APUs'!$A$1:$D$14,4,0) -> 2916.6667 | G35: =ROUNDUP(F35*(E35/21)/E2,0) -> 0
A36: ED-7 | B36: =VLOOKUP(A36,'Componentes APUs'!$A$1:$D$14,2,0) -> Capuchon | D36: =VLOOKUP(A36,'Componentes APUs'!$A$1:$D$14,3,0) -> U | E36: =SUM(C10:C15) -> 0 | F36: =VLOOKUP(A36,'Componentes APUs'!$A$1:$D$14,4,0) -> 2525.2525 | G36: =ROUNDUP(F36*(E36/21)/E2,0) -> 0
A37: ED-8 | B37: =VLOOKUP(A37,'Componentes APUs'!$A$1:$D$14,2,0) -> Guantes Protectores - ingeniero reforzados | D37: =VLOOKUP(A37,'Componentes APUs'!$A$1:$D$14,3,0) -> Par | E37: =C12+C13+C15 -> 0 | F37: =VLOOKUP(A37,'Componentes APUs'!$A$1:$D$14,4,0) -> 2525.2525 | G37: =ROUNDUP(F37*(E37/21)/E2,0) -> 0
A38: ED-9 | B38: =VLOOKUP(A38,'Componentes APUs'!$A$1:$D$14,2,0) -> Impermeable (pantalon camisa) | D38: =VLOOKUP(A38,'Componentes APUs'!$A$1:$D$14,3,0) -> U | E38: =SUM(C10:C15) -> 0 | F38: =VLOOKUP(A38,'Componentes APUs'!$A$1:$D$14,4,0) -> 3750 | G38: =ROUNDUP(F38*(E38/21)/E2,0) -> 0
A39: ED-10 | B39: =VLOOKUP(A39,'Componentes APUs'!$A$1:$D$14,2,0) -> Jean Dielectrico | D39: =VLOOKUP(A39,'Componentes APUs'!$A$1:$D$14,3,0) -> U | E39: =SUM(C10:C15) -> 0 | F39: =VLOOKUP(A39,'Componentes APUs'!$A$1:$D$14,4,0) -> 7575.7576 | G39: =ROUNDUP(F39*(E39/21)/E2,0) -> 0
A40: ED-11 | B40: =VLOOKUP(A40,'Componentes APUs'!$A$1:$D$14,2,0) -> Casco dielectrico Tipo 2 Clase E con barboquejo | D40: =VLOOKUP(A40,'Componentes APUs'!$A$1:$D$14,3,0) -> U | E40: =IF(A12="MO-3",C12,0) -> 0 | F40: =VLOOKUP(A40,'Componentes APUs'!$A$1:$D$14,4,0) -> 7500 | G40: =ROUNDUP(F40*(E40/21)/E2,0) -> 0
A41: ED-12 | B41: =VLOOKUP(A41,'Componentes APUs'!$A$1:$D$14,2,0) -> Kit de rescate para trabajo en alturas | D41: =VLOOKUP(A41,'Componentes APUs'!$A$1:$D$14,3,0) -> U | E41: =IF(AND(A12="MO-3",C12=2),1,0) -> 0 | F41: =VLOOKUP(A41,'Componentes APUs'!$A$1:$D$14,4,0) -> 37500 | G41: =ROUNDUP(F41*(E41/21)/E2,0) -> 0
A42: ED-13 | B42: =VLOOKUP(A42,'Componentes APUs'!$A$1:$D$14,2,0) -> Equipo completo para trabajo en alturas con pretales (Arnes dielectrico, 1 mosqueton de seguridad, tie off dielectrico, eslinga de posicionamiento, juego de pretales) | D42: =VLOOKUP(A42,'Componentes APUs'!$A$1:$D$14,3,0) -> U | E42: =IF(A12="MO-3",C12,0) -> 0 | F42: =VLOOKUP(A42,'Componentes APUs'!$A$1:$D$14,4,0) -> 26041.667 | G42: =ROUNDUP(F42*(E42/21)/E2,0) -> 0
A43: Subtotal D | G43: =SUM(G30:G42) -> 0
...

Sheet Presupuesto
C1: ACTIVIDAD | D1: UNIDAD | G1: CANTIDAD | J1: COSTOS
J2: VALOR UNITARIO | K2: BARAYA | L2: TESALIA | M2: QUIRINAL | N2: TESORO | O2: URDANETA
E3: Baraya | F3: Tesalia | G3: Quirinal | H3: Tesoro | I3: Urdaneta
C4: OBRA CIVIL | K4: =K15+K5+K22+K45+K94+K144+K162 -> 1.7476531e+09 | L4: =L15+L5+L22+L45+L94+L144+L162 -> 1.4803857e+09 | M4: =M15+M5+M22+M45+M94+M144+M162 -> 2.6640022e+09 | N4: =N15+N5+N22+N45+N94+N144+N162 -> 2.7201052e+09 | O4: =O15+O5+O22+O45+O94+O144+O162 -> 2.172842e+09
C5: PRELIMINARES | K5: =SUM(K6:K14) -> 2.9648954e+08 | L5: =SUM(L6:L14) -> 2.5357069e+08 | M5: =SUM(M6:M14) -> 2.7126841e+08 | N5: =SUM(N6:N14) -> 3.1738699e+08 | O5: =SUM(O6:O14) -> 2.1852945e+08
A6: 001 | B6: =A6&"_OC" -> 001_OC | C6: COMPLEMENTACIÓN Y/O AJUSTE A ESTUDIOS Y DISEÑOS (INCLUYE LEVANTAMIENTO TOPOGRÁFICO, ESTUDIO DE SUELO, DISEÑO HIDRÁULICO E HIDROSANITARIO, DISEÑO ELÉCTRICO, DISEÑO ESTRUCTURAL) | D6: GB | E6: 1 | F6: 1 | G6: 1 | H6: 1 | I6: 1 | J6: =APUs!G54 -> 20800000 | K6: =$J6*E6 -> 20800000 | L6: =$J6*F6 -> 20800000 | M6: =$J6*G6 -> 20800000 | N6: =$J6*H6 -> 20800000 | O6: =$J6*I6 -> 20800000
A7: 002 | B7: =A7&"_OC" -> 002_OC | C7: LIMPIEZA DE LOTE, PARA QUITAR MALEZA Y PODAR CÉSPED | D7: M2 | E7: =E16 -> 3117 | F7: =F16 -> 2524 | G7: =G16 -> 2763.79 | H7: =H16 -> 3401 | I7: =I16 -> 2043 | J7: =APUs!G125 -> 35055 | K7: =$J7*E7 -> 109266435 | L7: =$J7*F7 -> 88478820 | M7: =$J7*G7 -> 96884658 | N7: =$J7*H7 -> 119222055 | O7: =$J7*I7 -> 71617365
A8: 003 | B8: =A8&"_OC" -> 003_OC | C8: VALLA DE INFORMACIÓN DE 2,00 X 4,00 M | D8: UN | E8: 1 | F8: 1 | G8: 1 | H8: 1 | I8: 1 | J8: =APUs!G194 -> 5491990 | K8: =$J8*E8 -> 5491990 | L8: =$J8*F8 -> 5491990 | M8: =$J8*G8 -> 5491990 | N8: =$J8*H8 -> 5491990 | O8: =$J8*I8 -> 5491990
A9: 004 | B9: =A9&"_OC" -> 004_OC | C9: DESCAPOTE Y LIMPIEZA DE TERRENO | D9: M2 | E9: =E7 -> 3117 | F9: =F7 -> 2524 | G9: =G7 -> 2763.79 | H9: =H7 -> 3401 | I9: =I7 -> 2043 | J9: =APUs!G263 -> 34153 | K9: =$J9*E9 -> 106454901 | L9: =$J9*F9 -> 86202172 | M9: =$J9*G9 -> 94391720 | N9: =$J9*H9 -> 116154353 | O9: =$J9*I9 -> 69774579
A10: 005 | B10: =A10&"_OC" -> 005_OC | C10: TALA Y CARGUE DE ARBOL CON ALTURA DE HASTA 10 METROS (DESDE LA PARTE RADICULAR) | D10: UN | E10: 2 | F10: 2 | G10: 5 | H10: 5 | I10: 0 | J10: =APUs!G332 -> 114241 | K10: =$J10*E10 -> 228482 | L10: =$J10*F10 -> 228482 | M10: =$J10*G10 -> 571205 | N10: =$J10*H10 -> 571205 | O10: =$J10*I10 -> 0
A11: 006 | B11: =A11&"_OC" -> 006_OC | C11: DISPOSICION FINAL DEL MATERIAL EN BOTADERO AUTORIZADO | D11: M3 | E11: =E16*0.2 -> 623.4 | F11: =F16*0.2 -> 504.8 | G11: =G16*0.2 -> 552.758 | H11: =H16*0.2 -> 680.2 | I11: =I16*0.2 -> 408.6 | J11: =APUs!G400 -> 15839 | K11: =$J11*E11 -> 9874032.6 | L11: =$J11*F11 -> 7995527.2 | M11: =$J11*G11 -> 8755134 | N11: =$J11*H11 -> 10773688 | O11: =$J11*I11 -> 6471815.4
A12: 007 | B12: =A12&"_OC" -> 007_OC | C12: CAMPAMENTO E INSTALACIONES PROVISIONALES, INCLUYE CERRAMIENTO EN MALLA VERDE | D12: M2 | E12: 50 | F12: 50 | G12: 50 | H12: 50 | I12: 50 | J12: =APUs!G475 -> 291240 | K12: =$J12*E12 -> 14562000 | L12: =$J12*F12 -> 14562000 | M12: =$J12*G12 -> 14562000 | N12: =$J12*H12 -> 14562000 | O12: =$J12*I12 -> 14562000
A13: 008 | B13: =A13&"_OC" -> 008_OC | C13: PROVISIONAL DE ENERGÍA | D13: UN | E13: 1 | F13: 1 | G13: 1 | H13: 1 | I13: 1 | J13: =APUs!G555 -> 27431501 | K13: =$J13*E13 -> 27431501 | L13: =$J13*F13 -> 27431501 | M13: =$J13*G13 -> 27431501 | N13: =$J13*H13 -> 27431501 | O13: =$J13*I13 -> 27431501
A14: 009 | B14: =A14&"_OC" -> 009_OC | C14: PROVISIONAL DE AGUA | D14: UN | E14: 1 | F14: 1 | G14: 1 | H14: 1 | I14: 1 | J14: =APUs!G627 -> 2380200 | K14: =$J14*E14 -> 2380200 | L14: =$J14*F14 -> 2380200 | M14: =$J14*G14 -> 2380200 | N14: =$J14*H14 -> 2380200 | O14: =$J14*I14 -> 2380200
C15: ADECUACIONES DE TERRENO | K15: =SUM(K16:K21) -> 471951301 | L15: =SUM(L16:L21) -> 229484629 | M15: =SUM(M16:M21) -> 4.7480222e+08 | N15: =SUM(N16:N21) -> 204436087 | O15: =SUM(O16:O21) -> 79919649
A16: 010 | B16: =A16&"_OC" -> 010_OC | C16: LOCALIZACIÓN Y REPLANTEO | D16: M2 | E16: =2194+424+499 -> 3117 | F16: 2524 | G16: =2763.79 -> 2763.79 | H16: 3401 | I16: 2043 | J16: =APUs!G692 -> 4226 | K16: =$J16*E16 -> 13172442 | L16: =$J16*F16 -> 10666424 | M16: =$J16*G16 -> 11679777 | N16: =$J16*H16 -> 14372626 | O16: =$J16*I16 -> 8633718
A17: 011 | B17: =A17&"_OC" -> 011_OC | C17: EXCAVACIÓN MECANICA EN MATERIAL COMUN (INCLUYE CORTE Y CARGUE) | D17: M3 | E17: 5629 | F17: 1660 | G17: 48 | H17: 1205 | I17: 958 | J17: =APUs!G760 -> 41291 | K17: =$J17*E17 -> 232427039 | L17: =$J17*F17 -> 68543060 | M17: =$J17*G17 -> 1981968 | N17: =$J17*H17 -> 49755655 | O17: =$J17*I17 -> 39556778
A18: 006 | B18: =A18&"_OC" -> 006_OC | C18: DISPOSICION FINAL DEL MATERIAL EN BOTADERO AUTORIZADO | D18: M3 | E18: =E17-49 -> 5580 | F18: =1660-474 -> 1186 | G18: 0 | H18: =1205-689 -> 516 | I18: =958-190 -> 768 | J18: =APUs!G400 -> 15839 | K18: =$J18*E18 -> 88381620 | L18: =$J18*F18 -> 18785054 | M18: =$J18*G18 -> 0 | N18: =$J18*H18 -> 8172924 | O18: =$J18*I18 -> 12164352
A19: 013 | B19: =A19&"_OC" -> 013_OC | C19: RELLENO EN MATERIAL SELECCIONADO, COMPACTADO | D19: M3 | E19: 0 | F19: 0 | G19: =3450-G17 -> 3402 | H19: 0 | I19: 0 | J19: =APUs!G829 -> 79977 | K19: =$J19*E19 -> 0 | L19: =$J19*F19 -> 0 | M19: =$J19*G19 -> 272081754 | N19: =$J19*H19 -> 0 | O19: =$J19*I19 -> 0
A20: 014 | B20: =A20&"_OC" -> 014_OC | C20: RELLENO CON GRAVILLA | D20: M3 | E20: =(700+500*2)*0.2 -> 340 | F20: 307 | G20: =(1108+322+850-440)*0.2 -> 368 | H20: =(2642-130-44-203-64-133-64-434)*0.2 -> 314 | I20: =(460+250+802-450)*0.2 -> 212.4 | J20: =APUs!G896 -> 92113 | K20: =$J20*E20 -> 31318420 | L20: =$J20*F20 -> 28278691 | M20: =$J20*G20 -> 33897584 | N20: =$J20*H20 -> 28923482 | O20: =$J20*I20 -> 19564801
A21: 015 | B21: =A21&"_OC" -> 015_OC | C21: REVEGETACIÓN Y EMPRADIZADO | D21: M2 | E21: 310 | F21: 300 | G21: =61+300+90 -> 451 | H21: 300 | I21: 0 | J21: =APUs!G965 -> 344038 | K21: =$J21*E21 -> 106651780 | L21: =$J21*F21 -> 103211400 | M21: =$J21*G21 -> 155161138 | N21: =$J21*H21 -> 103211400 | O21: =$J21*I21 -> 0
C22: DISEÑO ESTRUCTURAL (CIMENTACIÓN) | K22: =K23+K37 -> 292715309 | L22: =L23+L37 -> 292194955 | M22: =M23+M37 -> 523874980 | N22: =N23+N37 -> 543367941 | O22: =O23+O37 -> 498946163
C23: CÁRCAMOS | K23: =SUM(K24:K36) -> 93435491 | L23: =SUM(L24:L36) -> 92915137 | M23: =SUM(M24:M36) -> 285560110 | N23: =SUM(N24:N36) -> 331076439 | O23: =SUM(O24:O36) -> 280148819
A24: 016 | B24: =A24&"_OC" -> 016_OC | C24: CARCAMO DE 40X60 CM. SEGÚN ESPECIFICACIONES EN PLANO. INCLUYE EXCAVACIÓN | D24: ML | E24: =10*2+22*2+7+13+5 -> 89 | F24: =10*2+22*2+7+13+5 -> 89 | G24: =26+10+24+7+10 -> 77 | H24: =26+10+24+7+10 -> 77 | I24: =26+10+24+7+10 -> 77 | J24: =APUs!G1034 -> 528081 | K24: =$J24*E24 -> 46999209 | L24: =$J24*F24 -> 46999209 | M24: =$J24*G24 -> 40662237 | N24: =$J24*H24 -> 40662237 | O24: =$J24*I24 -> 40662237
A25: 017 | B25: =A25&"_OC" -> 017_OC | C25: CARCAMO DE 2,3 X 1,51 X 14,5 m. SEGÚN ESPECIFICACIONES EN PLANO. INCLUYE VIGAS DE SOPORTE DE CELDAS Y EXCAVACIÓN | D25: UN | E25: 0 | F25: 0 | G25: 1 | H25: 1 | I25: 1 | J25: =APUs!G1102 -> 40226556 | K25: =$J25*E25 -> 0 | L25: =$J25*F25 -> 0 | M25: =$J25*G25 -> 40226556 | N25: =$J25*H25 -> 40226556 | O25: =$J25*I25 -> 40226556
A26: 018 | B26: =A26&"_OC" -> 018_OC | C26: CARCAMO DE 2,7 X 1,4 X 9 m. SEGÚN ESPECIFICACIONES EN PLANO. INCLUYE VIGAS DE SOPORTE DE CELDAS Y EXCAVACIÓN | D26: UN | E26: 0 | F26: 0 | G26: 1 | H26: 1 | I26: 1 | J26: =APUs!G1170 -> 24818083 | K26: =$J26*E26 -> 0 | L26: =$J26*F26 -> 0 | M26: =$J26*G26 -> 24818083 | N26: =$J26*H26 -> 24818083 | O26: =$J26*I26 -> 24818083
A27: 019 | B27: =A27&"_OC" -> 019_OC | C27: TAPA EN ALFAJOR (1,10X 1 METROS) (CÁRCAMO 34,5 kV) | D27: ML | E27: 0 | F27: 0 | G27: 22 | H27: 22 | I27: 22 | J27: =APUs!G1239 -> 567987 | K27: =$J27*E27 -> 0 | L27: =$J27*F27 -> 0 | M27: =$J27*G27 -> 12495714 | N27: =$J27*H27 -> 12495714 | O27: =$J27*I27 -> 12495714
A28: 020 | B28: =A28&"_OC" -> 020_OC | C28: TAPA EN ALFAJOR (1 X1 METROS) (CÁRCAMO 13,8 kV) | D28: ML | E28: 0 | F28: 0 | G28: =13 -> 13 | H28: =13 -> 13 | I28: =13 -> 13 | J28: =APUs!G1310 -> 531632 | K28: =$J28*E28 -> 0 | L28: =$J28*F28 -> 0 | M28: =$J28*G28 -> 6911216 | N28: =$J28*H28 -> 6911216 | O28: =$J28*I28 -> 6911216
A29: 021 | B29: =A29&"_OC" -> 021_OC | C29: TAPA EN ALFAJOR (0,8X 1 METROS) (CÁRCAMO BAJA TENSIÓN) | D29: ML | E29: =7+13 -> 20 | F29: =7+13 -> 20 | G29: =G24 -> 77 | H29: =H24 -> 77 | I29: =I24 -> 77 | J29: =APUs!G1381 -> 458924 | K29: =$J29*E29 -> 9178480 | L29: =$J29*F29 -> 9178480 | M29: =$J29*G29 -> 35337148 | N29: =$J29*H29 -> 35337148 | O29: =$J29*I29 -> 35337148
A30: 022 | B30: =A30&"_OC" -> 022_OC | C30: TAPA TIPO A (1 X0.5 M) | D30: UN | E30: 118 | F30: 117 | G30: 0 | H30: 0 | I30: 0 | J30: =APUs!G1450 -> 100919 | K30: =$J30*E30 -> 11908442 | L30: =$J30*F30 -> 11807523 | M30: =$J30*G30 -> 0 | N30: =$J30*H30 -> 0 | O30: =$J30*I30 -> 0
A31: 023 | B31: =A31&"_OC" -> 023_OC | C31: TAPA TIPO B (DIMENSIÓN VARIABLE) | D31: UN | E31: 8 | F31: 8 | G31: 0 | H31: 0 | I31: 0 | J31: =APUs!G1519 -> 100919 | K31: =$J31*E31 -> 807352 | L31: =$J31*F31 -> 807352 | M31: =$J31*G31 -> 0 | N31: =$J31*H31 -> 0 | O31: =$J31*I31 -> 0
A32: 024 | B32: =A32&"_OC" -> 024_OC | C32: TAPA TIPO C (86 X 16 X 1018 X 1216) (ESQUINERA SEGÚN PLANOS) | D32: UN | E32: 4 | F32: 4 | G32: 0 | H32: 0 | I32: 0 | J32: =APUs!G1590 -> 105844 | K32: =$J32*E32 -> 423376 | L32: =$J32*F32 -> 423376 | M32: =$J32*G32 -> 0 | N32: =$J32*H32 -> 0 | O32: =$J32*I32 -> 0
A33: 025 | B33: =A33&"_OC" -> 025_OC | C33: CAJA DE INSPECCIÓN (NORMA EH RSS-033) BAJA TENSIÓN. INCLUYE EXCAVACIÓN | D33: UN | E33: 7 | F33: 7 | G33: 1 | H33: 1 | I33: 1 | J33: =APUs!G1659 -> 3014100 | K33: =$J33*E33 -> 21098700 | L33: =$J33*F33 -> 21098700 | M33: =$J33*G33 -> 3014100 | N33: =$J33*H33 -> 3014100 | O33: =$J33*I33 -> 3014100
A34: 026 | B34: =A34&"_OC" -> 026_OC | C34: CAJA DE INSPECCIÓN (NORMA EH RSS-041-2) - 13,8 Kv. INCLUYE EXCAVACIÓN | D34: UN | G34: 11 | H34: 15 | I34: 12 | J34: =APUs!G1728 -> 4714065 | K34: =$J34*E34 -> 0 | L34: =$J34*F34 -> 0 | M34: =$J34*G34 -> 51854715 | N34: =$J34*H34 -> 70710975 | O34: =$J34*I34 -> 56568780
A35: 027 | B35: =A35&"_OC" -> 027_OC | C35: CAJA DE INSPECCIÓN (NORMA EH RSS-152-2) - 34,5 kV. INCLUYE EXCAVACIÓN | D35: UN | G35: 9 | H35: 13 | I35: 8 | J35: =APUs!G1797 -> 7357085 | K35: =$J35*E35 -> 0 | L35: =$J35*F35 -> 0 | M35: =$J35*G35 -> 66213765 | N35: =$J35*H35 -> 95642105 | O35: =$J35*I35 -> 58856680
A36: 028 | B36: =A36&"_OC" -> 028_OC | C36: REFUERZO PARA BANCO DE DUCTO DE 0,8X0,1 m 3000 PSI PARA CRUCE DE VIAS (NORMA ENEL CS-221) | D36: ML | E36: =12+14+10 -> 36 | F36: =6+5+5+15 -> 31 | G36: =6*8 -> 48 | H36: =6+9 -> 15 | I36: =6+9 -> 15 | J36: =APUs!G1863 -> 83887 | K36: =$J36*E36 -> 3019932 | L36: =$J36*F36 -> 2600497 | M36: =$J36*G36 -> 4026576 | N36: =$J36*H36 -> 1258305 | O36: =$J36*I36 -> 1258305
C37: TRANSFORMADOR | K37: =SUM(K38:K43) -> 199279818 | L37: =SUM(L38:L43) -> 199279818 | M37: =SUM(M38:M43) -> 238314870 | N37: =SUM(N38:N43) -> 212291502 | O37: =SUM(O38:O43) -> 218797344
A38: 029 | B38: =A38&"_OC" -> 029_OC | C38: EXCAVACION MANUAL EN MATERIAL COMÚN | D38: M3 | E38: =25*2+0.5*E40+27*4 -> 170 | F38: =25*2+0.5*F40+27*4 -> 170 | G38: =25*2+0.5*G40+27*4 -> 182 | H38: =25*2+0.5*H40+27*4 -> 174 | I38: =25*2+0.5*I40+27*4 -> 176 | J38: =APUs!G1928 -> 38345 | K38: =$J38*E38 -> 6518650 | L38: =$J38*F38 -> 6518650 | M38: =$J38*G38 -> 6978790 | N38: =$J38*H38 -> 6672030 | O38: =$J38*I38 -> 6748720
A39: 030 | B39: =A39&"_OC" -> 030_OC | C39: FOSO DE TRANSFORMADOR Y CARRILERAS SEGÚN DISEÑO. INCLUYE RIEL DE DESPLAZAMIENTO. | D39: UN | E39: 2 | F39: 2 | G39: 2 | H39: 2 | I39: 2 | J39: =APUs!G1997 -> 42138921 | K39: =$J39*E39 -> 84277842 | L39: =$J39*F39 -> 84277842 | M39: =$J39*G39 -> 84277842 | N39: =$J39*H39 -> 84277842 | O39: =$J39*I39 -> 84277842
A40: 031 | B40: =A40&"_OC" -> 031_OC | C40: CARRILERA DE 1,2*0,4 M, PARA TRANSFORMADOR SEGÚN DISEÑO. INCLUYE RIEL DE DESPLAZAMIENTO. | D40: ML | E40: =6*4 -> 24 | F40: =6*4 -> 24 | G40: =12*4 -> 48 | H40: =8*4 -> 32 | I40: =9*4 -> 36 | J40: =APUs!G2065 -> 1607288 | K40: =$J40*E40 -> 38574912 | L40: =$J40*F40 -> 38574912 | M40: =$J40*G40 -> 77149824 | N40: =$J40*H40 -> 51433216 | O40: =$J40*I40 -> 57862368
...

Sheet IPP
A1: Fecha | B1: Índice de Precios del Productor (IPP)
A2: yyyy/mm/dd | B2: Índice
A3: 1999/06/30 | B3: 43.87
A4: 1999/07/31 | B4: 44.59
A5: 1999/08/31 | B5: 45.24
A6: 1999/09/30 | B6: 45.71
A7: 1999/10/31 | B7: 46.27
A8: 1999/11/30 | B8: 46.89
A9: 1999/12/31 | B9: 47.41
A10: 2000/01/31 | B10: 48.07
A11: 2000/02/29 | B11: 49.19
A12: 2000/03/31 | B12: 49.87
A13: 2000/04/30 | B13: 50.36
A14: 2000/05/31 | B14: 50.83
... A220: 2017/07/31 | B220: 107.1
A221: 2017/08/31 | B221: 107.7 | C221: =$B$310/B220 -> 1.75845
A222: 2017/09/30 | B222: 108.17 | C222: =$B$310/B221 -> 1.7486537
A223: 2017/10/31 | B223: 109.04 | C223: =$B$310/B222 -> 1.7410557
A224: 2017/11/30 | B224: 110.76 | C224: =$B$310/B223 -> 1.7271643
A225: 2017/12/31 | B225: 111.29 | C225: =$B$310/B224 -> 1.7003431
A226: 2018/01/31 | B226: 111.5 | C226: =$B$310/B225 -> 1.6922455
A227: 2018/02/28 | B227: 111.35 | C227: =$B$310/B226 -> 1.6890583
A228: 2018/03/31 | B228: 111.14 | C228: =$B$310/B227 -> 1.6913336
A229: 2018/04/30 | B229: 111.41 | C229: =$B$310/B228 -> 1.6945294
A230: 2018/05/31 | B230: 113.86 | C230: =$B$310/B229 -> 1.6904228
A231: 2018/06/30 | B231: 113.72 | C231: =$B$310/B230 -> 1.6540488
A232: 2018/07/31 | B232: 113.45 | C232: =$B$310/B231 -> 1.6560851
... A310: 2025/01/31 | B310: 188.33 | C310: =$B$310/B309 -> 1.0102457
A313: Descargado de sistema del Banco de la República viernes, 7 de febrero de 2025 1:51:54 p. m.

Sheet N Bahias
A1: BAHÍAS ACTIVAS | F1: ELEMENTOS POR BAHÍA | J1: TOTAL EQUIPOS EN 34,5 kV | P1: TOTAL EQUIPOS EN 13,8 kV
A2: Tensión | B2: DDP | C2: Activa | D2: Bahía de Línea | F2: Equipo | G2: Bahía de Línea | H2: Bahía de Trafo | J2: Cod | K2: Equipo | L2: Bahía de Línea | M2: Bahía de Trafo | N2: Total | P2: Cod | Q2: Elementos por S/E | R2: Bahía de Línea | S2: Bahía de Trafo | T2: Total
A3: 34.5 | B3: FORTALECILLAS | C3: SI | D3: L | F3: DPS | G3: 3 | H3: 3 | J3: 1.1 | K3: Transformador de Potencia | M3: 1 | N3: =SUM(L3:M3) -> 1
A4: 34.5 | B4: COLOMBIA | C4: SI | D4: L | F4: Reconectador/Interruptor | G4: 1 | H4: 1 | J4: 2.1 | K4: DPS | L4: =G3*B$21 -> 12 | M4: =H3*C$21 -> 3 | N4: =SUM(L4:M4) -> 15 | P4: 1.2 | Q4: DPS | R4: =G3*B$22 -> 9 | S4: =H3*C$22 -> 3 | T4: =SUM(R4:S4) -> 12
A5: 34.5 | B5: AIPE | C5: SI | D5: L | F5: Seccionador Tripolar | G5: 1 | H5: 1 | J5: 3.1 | K5: Reconectador/Interruptor | L5: =G4*B$21 -> 4 | M5: =H4*C$21 -> 1 | N5: =SUM(L5:M5) -> 5 | P5: 2.2 | Q5: Reconectador/Interruptor | R5: =G4*B$22 -> 3 | S5: =H4*C$22 -> 1 | T5: =SUM(R5:S5) -> 4
A6: 34.5 | B6: TRAFO 1 | C6: SI | D6: T | F6: Seccionador con cuchilla PT | G6: 1 | H6: 0 | J6: 4.1 | K6: Seccionador Tripolar | L6: =G5*B$21 -> 4 | M6: =H5*C$21 -> 1 | N6: =SUM(L6:M6) -> 5 | P6: 3.2 | Q6: Seccionador Tripolar | R6: =G5*B$22 -> 3 | S6: =H5*C$22 -> 1 | T6: =SUM(R6:S6) -> 4
A7: 34.5 | B7: SERV AUX | C7: SI | D7: Aux | F7: TC | G7: 3 | H7: 3 | J7: 5.1 | K7: Seccionador con cuchilla PT | L7: =G6*B$21 -> 4 | M7: =H6*C$21 -> 0 | N7: =SUM(L7:M7) -> 4 | P7: 4.2 | Q7: Seccionador con cuchilla PT | R7: =G6*B$22 -> 3 | S7: =H6*C$22 -> 0 | T7: =SUM(R7:S7) -> 3
A8: 34.5 | B8: TRAFO 2 - RESER | C8: NO | D8: T | F8: Medidor | G8: 1 | H8: 1 | J8: 6.1 | K8: TC General | L8: =G7*B$21 -> 12 | M8: =H7*C$21 -> 3 | N8: =SUM(L8:M8) -> 15 | P8: 5.2 | Q8: TC General | R8: =G7*B$22 -> 9 | S8: =H7*C$22 -> 3 | T8: =SUM(R8:S8) -> 12
A9: 34.5 | B9: RESERVA LÍNEA 1 | C9: NO | D9: L | J9: 7.1 | K9: TP General | L9: 3 | M9: 0 | N9: =SUM(L9:M9) -> 3 | P9: 6.2 | Q9: TP General | R9: 3 | S9: 0 | T9: =SUM(R9:S9) -> 3
A10: 34.5 | B10: RESERVA LÍNEA 2 | C10: NO | D10: L | J10: 8.1 | K10: TP Particular | L10: 1 | M10: 0 | N10: =SUM(L10:M10) -> 1 | P10: 7.2 | Q10: =H18 -> 0 | R10: =H19 -> 0 | S10: 0 | T10: =SUM(R10:S10) -> 0
A11: 13.8 | B11: LAURELES-PATIA | C11: SI | D11: L | J11: 9.1 | K11: =B20 -> Bahías de Línea | L11: =B21 -> 4 | M11: 0 | N11: =SUM(L11:M11) -> 4 | P11: 8.2 | Q11: =I18 -> 0 | R11: 0 | S11: =I19 -> 0 | T11: =SUM(R11:S11) -> 0
A12: 13.8 | B12: SAN ANDRÉS | C12: SI | D12: L | J12: 10.1 | K12: =C20 -> Bahías de Trafo | L12: 0 | M12: =C21 -> 1 | N12: =SUM(L12:M12) -> 1 | P12: 9.2 | Q12: Medidor | R12: =M6*H$21 -> 0 | S12: =N6*I$21 -> 0 | T12: =SUM(R12:S12) -> 0
A13: 13.8 | B13: URBANO | C13: SI | D13: L | J13: 11.1 | K13: Medidor | L13: =G8*B$21 -> 4 | M13: =H8*C$21 -> 1 | N13: =SUM(L13:M13) -> 5
A14: 13.8 | B14: SERV AUX | C14: SI | D14: Aux
A15: 13.8 | B15: TRAFO 1 | C15: SI | D15: T
A16: 13.8 | B16: TRAFO 2 - RESER | C16: NO | D16: T
A17: 13.8 | B17: RESERVA LÍNEA 2 | C17: NO | D17: L
A18: 13.8 | B18: RESERVA LÍNEA 2 | C18: NO | D18: L
A20: Tensión | B20: Bahías de Línea | C20: Bahías de Trafo | D20: Bahías Aux
A21: 34.5 | B21: 4 | C21: =COUNTIFS($D$3:$D$18,"T",$C$3:$C$18,"SI",$A$3:$A$18,$A21) -> 1 | D21: =COUNTIFS($D$3:$D$18,"Aux",$C$3:$C$18,"SI",$A$3:$A$18,$A$21) -> 1
A22: 13.8 | B22: =COUNTIFS($D$3:$D$18,"L",$C$3:$C$18,"SI",$A$3:$A$18,$A$21) -> 3 | C22: =COUNTIFS($D$3:$D$18,"T",$C$3:$C$18,"SI",$A$3:$A$18,$A22) -> 1 | D22: =COUNTIFS($D$3:$D$18,"Aux",$C$3:$C$18,"SI",$A$3:$A$18,$A$21) -> 1
A23: Total | B23: =SUM(B21:B22) -> 7 | C23: =SUM(C21:C22) -> 2 | D23: =SUM(D21:D22) -> 2
A25: Descripción | B25: Metros
A26: Metros Caseta a Patio | B26: 15
A27: Bahías Equipadas 34,5 kV | B27: 5
A28: Bahías Equipadas 13,8 kV | B28: 4
A29: Pase de Vía | B29: 21
A30: Tubos 4" | B30: 8
A31: Tubos 3" | B31: 4
A32: Tubos 2" | B32: 3
A33: Tubos 1 1/2" | B33: 4

Sheet Componentes APUs
A1: Referencia | B1: Descripción | C1: Unidad | D1: Vr. Unitario ($) | E1: Vida Util (Años) | F1: Valor ED | H1: Referencia | I1: Descripción | J1: Fac. Sal | K1: Jornal ($) | L1: Prestaciones ($) | N1: Referencia | O1: Descripción | P1: Unidad | Q1: Vr. Unitario ($) | S1: Referencia | T1: Descripción | U1: Unidad | V1: Vr. Unitario ($)
A2: ED-1 | B2: Camisa indigo sin partes metalicas | C2: U | D2: =F2/(E2*12) -> 8585.8586 | E2: 0.33 | F2: 34000 | H2: MO-1 | I2: Ingeniero Residente de Obra | J2: 4 | K2: =J2*IF(J2>2,1423500,(1423500+200000))/21 -> 271142.86 | L2: =0.6*K2 -> 162685.71 | N2: TV-1 | O2: Camioneta | P2: U | Q2: 5500000 | S2: EH-1 | T2: Juego Llaves | U2: U | V2: 9167
A3: ED-2 | B3: Bota de seguridad dielectrica | C3: Par | D3: =F3/(E3*12) -> 7500 | E3: 1 | F3: 90000 | H3: MO-2 | I3: Tecnico Supervisor | J3: 2.3 | K3: =J3*IF(J3>2,1423500,(1423500+200000))/21 -> 155907.14 | L3: =0.6*K3 -> 93544.286 | N3: TV-2 | O3: Grúa Hidráulica | P3: U | Q3: 21000000 | S3: EH-2 | T3: Manila de servicio | U3: U | V3: 2333
A4: ED-3 | B4: Casco dielectrico Tipo 1 Clase E con barbuquejo | C4: U | D4: =F4/(E4*12) -> 10101.01 | E4: 0.33 | F4: 40000 | H4: MO-3 | I4: Tecnico Liniero | J4: 2 | K4: =J4*IF(J4>2,1423500,(1423500+200000))/21 -> 154619.05 | L4: =0.6*K4 -> 92771.429 | N4: TV-3 | O4: Camabaja | P4: TON/KM | Q4: 611 | S4: EH-3 | T4: Tula portaherramientas | U4: U | V4: 1250
A5: ED-4 | B5: Correa plastica y antiflama | C5: U | D5: =F5/(E5*12) -> 3787.8788 | E5: 0.33 | F5: 15000 | H5: MO-4 | I5: Ayudante Calificado | J5: 1.5 | K5: =J5*IF(J5>2,1423500,(1423500+200000))/21 -> 115964.29 | L5: =0.6*K5 -> 69578.571 | N5: TV-4 | O5: Volqueta | P5: U | Q5: =88263*21*8 -> 14828184 | S5: EH-4 | T5: Agarradoras | U5: U | V5: 125000
A6: ED-5 | B6: Gafas protectoras filtro UV | C6: U | D6: =F6/(E6*12) -> 2777.7778 | E6: 0.33 | F6: 11000 | H6: MO-5 | I6: Profesional en SST | J6: 2.5 | K6: =J6*IF(J6>2,1423500,(1423500+200000))/21 -> 169464.29 | L6: =0.6*K6 -> 101678.57 | N6: TV-5 | O6: Retroexcavadora | P6: U | Q6: =273992*21*8 -> 46030656 | S6: EH-5 | T6: Templadoras | U6: U | V6: 250000
A7: ED-6 | B7: Bota de seguridad PVC dielectrica | C7: Par | D7: =F7/(E7*12) -> 2916.6667 | E7: 2 | F7: 70000 | H7: MO-6 | I7: Ayudante No Calificado | J7: 1 | K7: =J7*IF(J7>2,1423500,(1423500+200000))/21 -> 77309.524 | L7: =0.6*K7 -> 46385.714 | N7: TV-6 | O7: Montacarga | P7: U | Q7: pendiente | S7: EH-6 | T7: Herramienta Menor | U7: U | V7: 75758
A8: ED-7 | B8: Capuchon | C8: U | D8: =F8/(E8*12) -> 2525.2525 | E8: 0.33 | F8: 10000 | H8: MO-7 | I8: Ayudante de Obra Civil | J8: 1 | K8: =J8*IF(J8>2,1423500,(1423500+200000))/21 -> 77309.524 | L8: =0.6*K8 -> 46385.714 | N8: TV-7 | O8: Vibrador de concreto | P8: U | Q8: =63070*21 -> 1324470 | S8: EH-7 | T8: =PROPER("MOLDE GRAFITO SOLDADURA EXOTÉRMICA EN X") -> Molde Grafito Soldadura Exotérmica En X | U8: U | V8: 239000
A9: ED-8 | B9: Guantes Protectores - ingeniero reforzados | C9: Par | D9: =F9/(E9*12) -> 2525.2525 | E9: 0.33 | F9: 10000 | H9: MO-8 | I9: Maestro de obra civil | J9: 2.5 | K9: =J9*IF(J9>2,1423500,(1423500+200000))/21 -> 169464.29 | L9: =0.6*K9 -> 101678.57 | N9: TV-8 | O9: Miniretroexcavadora | P9: M3 | Q9: 70000 | S9: EH-8 | T9: Equipo para trabajo con fibra óptica | U9: U | V9: =899*1.19*'Precio Monedas'!B2 -> 4814145
A10: ED-9 | B10: Impermeable (pantalon camisa) | C10: U | D10: =F10/(E10*12) -> 3750 | E10: 1 | F10: 45000 | H10: MO-9 | I10: Oficial de Obra Civil | J10: 1.5 | K10: =J10*IF(J10>2,1423500,(1423500+200000))/21 -> 115964.29 | L10: =0.6*K10 -> 69578.571 | N10: TV-9 | O10: Dumper de descarga Frontal 2T | P10: U | Q10: =26420.93*8*21 -> 4438716.2 | S10: EH-9 | T10: Diferencial 2 Toneladas | U10: U | V10: 474905
A11: ED-10 | B11: Jean Dielectrico | C11: U | D11: =F11/(E11*12) -> 7575.7576 | E11: 0.33 | F11: 30000 | H11: MO-10 | I11: Ingeniero Civil Residente de Obra | J11: 3 | K11: =J11*IF(J11>2,1423500,(1423500+200000))/21 -> 203357.14 | L11: =0.6*K11 -> 122014.29 | N11: TV-10 | O11: Rodillo Ligero | P11: U | Q11: =9975*8*21 -> 1675800
A12: ED-11 | B12: Casco dielectrico Tipo 2 Clase E con barboquejo | C12: U | D12: =F12/(E12*12) -> 7500 | E12: 1 | F12: 90000 | H12: MO-11 | I12: Ingeniero Especialista de Control y Protección Subestación | J12: 14 | K12: =J12*IF(J12>2,1423500,(1423500+200000))/21 -> 949000 | L12: =0.6*K12 -> 569400 | N12: TV-11 | O12: Motocultor | P12: U | Q12: =7695*8*21 -> 1292760
A13: ED-12 | B13: Kit de rescate para trabajo en alturas | C13: U | D13: =F13/(E13*12) -> 37500 | E13: 4 | F13: 1800000 | H13: MO-12 | I13: Técnico calificado para Comunicaciones | J13: 3 | K13: =J13*IF(J13>2,1423500,(1423500+200000))/21 -> 203357.14 | L13: =0.6*K13 -> 122014.29 | N13: TV-12 | O13: Concretera | P13: U | Q13: =3278*8*21 -> 550704
A14: ED-13 | B14: Equipo completo para trabajo en alturas con pretales (Arnes dielectrico, 1 mosqueton de seguridad, tie off dielectrico, eslinga de posicionamiento, juego de pretales) | C14: U | D14: =F14/(E14*12) -> 26041.667 | E14: 4 | F14: 1250000 | H14: MO-13 | I14: Oficial Eléctrico | J14: 2 | K14: =J14*IF(J14>2,1423500,(1423500+200000))/21 -> 154619.05 | L14: =0.6*K14 -> 92771.429 | N14: TV-13 | O14: Extendedora Asfáltica De Cadenas 110 Cv | P14: U | Q14: =141307*8*21 -> 23739576
H15: MO-14 | I15: Topografo | J15: 2 | K15: =J15*IF(J15>2,1423500,(1423500+200000))/21 -> 154619.05 | L15: =0.6*K15 -> 92771.429 | N15: TV-14 | O15: Rodillo Vibrante Tándem Autopropulsado, De 2300 Kg, Anchura De Trabajo 105 Cm | P15: U | Q15: =29162*8*21 -> 4899216
N16: TV-15 | O16: Compactador De Neumáticos Autopropulsado, De 12/22 T | P16: U | Q16: =102366*8*21 -> 17197488
N17: TV-16 | O17: Planta de asfalto en caliente continua de 120 toneladas de capacidad | P17: U | Q17: =675749.029432224*8*21 -> 1.1352584e+08
N18: TV-17 | O18: Cargador: potencia en el volante 125 hp, clasificación de rpm del motor 2300 | P18: U | Q18: =256739.231927711*8*21 -> 43132191
N19: TV-18 | O19: Compactador de rodillo potencia: 99 hp, peso: 8 toneladas | P19: U | Q19: =248057.228915663*21*8 -> 41673614
N20: TV-19 | O20: Terminadora de asfalto (Finisher), potencia en el volante 174 HP, R=20M3/H, velocidad de desplazamiento 114 m/min | P20: U | Q20: =197412.809400494*21*8 -> 33165352
N21: TV-20 | O21: Carrotanque de agua (1000 Galones) | P21: U | Q21: =124028.614457831*8*21 -> 20836807
N22: TV-21 | O22: Motoniveladora potencia 215 HP, ancho de cuchilla 4,27 m, peso 18 ton | P22: U | Q22: =221341.634782372*8*21 -> 37185395
N23: TV-22 | O23: Vibrocompactador, potencia 153 HP, peso 10 ton | P23: U | Q23: =232553.652108434*8*21 -> 39069014
N24: TV-23 | O24: Compresor (barrido y soplado) | P24: U | Q24: =53839.8571092257*21*8 -> 9045096
N25: TV-24 | O25: Vehículo delineador para aplicación de pintura con mínimo 2 boquillas (NTC 4744-2) | P25: U | Q25: 214489.08
N26: TV-25 | O26: CILINDRO COMPACTADOR BENITÍN DE 300 Kg | P26: U | Q26: =103154*21*8 -> 17329872
N27: TV-26 | O27: CARRETA BUGGIE, PALA, ZAPAPICO | P27: U | Q27: =429030*21*8 -> 72077040
N28: TV-27 | O28: MINICARGADOR CON OPERARIO | P28: U | Q28: =117332*21*8 -> 19711776
N29: TV-28 | O29: Cilindro compactador vibrador dynapac | P29: U | Q29: =141751.68*8*21 -> 23814282
N30: TV-29 | O30: Carrotanque agua | P30: U | Q30: =76057.8*8*21 -> 12777710
N31: TV-30 | O31: Compactador asfalto | P31: U | Q31: =117530.196*8*21 -> 19745073
N32: TV-31 | O32: Terminador de asfalto | P32: U | Q32: =154259.427*8*21 -> 25915584

Sheet Precio Monedas
A1: Moneda | B1: Valor
A2: Dólar Americano | B2: 4500
A3: Peso chileno | B3: 4.3
A4: Euro | B4: 4300
A5: Peso Mexicano | B5: 220
